Workbook

Sheet Обложка

Sheet Свод для мастеров
A2: Адрес объекта: ""
A3: Сводная смета
A4: площади
A5: площадь пола
A6: площадь стен
A7: наименование работ
A8: демонтажные работы
A9: черновые отделочные работы
A10: чистовые отделочные работы
A11: электромонтажные работы
A12: сантехнические работы
A13: подготовительные работы
A14: ИТОГО ПО РАБОТАМ | B14: =SUM($B$8, $B$9, $B$10, $B$11, $B$12, $B$13) -> 0
A15: ИТОГО СО СКИДКОЙ | B15: =$B$14-$B$14*$B$32 -> 0
A17: СТОИМОСТЬ РАБОТ | C17: руб
A18: СКИДКА | B18: =B17-B19 -> 0 | C18: руб
A19: РАБОТЫ С УЧЕТОМ СКИДКИ | C19: руб
A20: СПЕЦМОНТАЖ | B20: 0 | C20: руб
A21: ИТОГО СМЕТНАЯ СТОИМОСТЬ | B21: =B20+B19 -> 0 | C21: руб

Sheet См. для мастеров

Sheet RusName
A1: Смета | B1: Комната | C1: ФАЙЛ
A2: Смета по комна | B2: Комната(база) | C2: СОЗДАТЬ ЛИСТ СМЕТЫ
A3: Комната № | B3: Смета по комнате № | C3: СОЗДАТЬ ЛИСТЫ АКТА И ДОП. РАБОТ
A4: Смета по кухне | B4: Комната | C4: СОЗДАТЬ ЛИСТЫ СМЕТЫ
A5: Кухня № | B5: Кухня | C5: СОЗДАТЬ(ОБНОВИТЬ) СВОД
A6: Смета по ванно | B6: Ванная комната | C6: СОЗДАТЬ
A7: Ванная № | B7: Туалет
A8: Смета по туале | B8: Коридор
A9: Туалет № | B9: Кладовая
A10: Смета по корид | B10: Лоджия(балкон)
A11: Коридор № | B11: Электромонтаж
A12: Смета по кладо | B12: Спецмонтаж
A13: Кладовая № | B13: Кухня(база)
A14: Смета по лоджи | B14: Кухня
A15: Лоджия № | B15: Смета по кухне №
A16: Смета, электро | B16: Ванная комната(база)
A17: Электромонтаж | B17: Ванна
A18: Смета, спецмон | B18: Ванная комната
... A36: , эл_м | B36: Смета, спецмонтаж
A37: , спецмонтаж
A38: , сп_м
A39: Смета
A41: Прайс для расчета (М)
A42: Прайс для расчета (М)

Sheet xyz
A1: СМЕТА
A2: Комната | B2: Кухня | C2: Ванная комната | D2: Туалет | E2: Коридор | F2: Кладовая | G2: Лоджия(балкон) | H2: Электромонтаж | I2: Спецмонтаж
A3: 3 | B3: 1 | C3: 2 | E3: 1 | F3: 2 | H3: 1
A5: АКТ И ДОП. РАБОТЫ
A6: Комната | B6: Кухня | C6: Ванная комната | D6: Туалет | E6: Коридор | F6: Кладовая | G6: Лоджия(балкон) | H6: Электромонтаж | I6: Спецмонтаж

Sheet Комната(база)
A1: Периметр | T1: =G137 -> 0 | U1: =J137 -> 0
A2: =ROUND(D7*2+E7*2,2) -> 0 | T2: =G248 -> 0 | U2: =J248 -> 0
A3: Площадь пола | T3: =G362 -> 0 | U3: =J362 -> 0
A4: =ROUND(D7*E7,2) -> 0 | T4: 0 | U4: 0
A5: Площадь стен | C5: =#REF! -> #REF! | T5: =G372 -> 0 | U5: =J372 -> 0
A6: =ROUND(A2*F7-G7,2) -> #REF! | C6: Приложение№1 к договору № КС ____________ от ______________ 202_г. | D6: L,м/п | E6: B,м/п | F6: H,м/п | G6: Проем, м2 | T6: =G382 -> 0 | U6: =J382 -> 0
D7: 0 | E7: 0 | F7: =#REF! -> #REF! | G7: 0 | T7: =G383 -> 0 | U7: =J383 -> 0
C8: СМЕТА от "______"___________________202_г. | D8: =G385 -> #REF! | H8: Вып. | T8: =G385 -> #REF! | U8: =J385 -> 0
B10: =IF(SUM(B11:B136)>0,1,0) -> 0 | C10: Комната. Демонтажные работы | D10: ед. изм. | E10: кол-во | F10: цена | G10: сумма | I10: цена мастер | J10: сумма
B11: =IF(SUM(B12:B32)>0,1,0) -> 0 | C11: Полы
C12: Демонтаж плинтуса | D12: м/п | E12: =$A$2 -> 0 | F12: ='Прайс для расчета'!E5 -> 89.25 | G12: =F12*E12 -> 0 | I12: ='Прайс для расчета (М)'!E5 -> 44.625 | J12: =I12*E12 -> 0
C13: Демонтаж ламината, паркетной доски | D13: м2 | E13: =$A$4 -> 0 | F13: ='Прайс для расчета'!E6 -> 157.5 | G13: =F13*E13 -> 0 | I13: ='Прайс для расчета (М)'!E6 -> 78.75 | J13: =I13*E13 -> 0
C14: Демонтаж паркета штучного | D14: м2 | E14: =$A$4 -> 0 | F14: ='Прайс для расчета'!E7 -> 292.236 | G14: =F14*E14 -> 0 | I14: ='Прайс для расчета (М)'!E7 -> 146.118 | J14: =I14*E14 -> 0
C15: Демонтаж паркета шитового | D15: м2 | E15: =$A$4 -> 0 | F15: ='Прайс для расчета'!E8 -> 367.5 | G15: =F15*E15 -> 0 | I15: ='Прайс для расчета (М)'!E8 -> 183.75 | J15: =I15*E15 -> 0
C16: Демонтаж линолеума, ковролина | D16: м2 | E16: =$A$4 -> 0 | F16: ='Прайс для расчета'!E9 -> 120.771 | G16: =F16*E16 -> 0 | I16: ='Прайс для расчета (М)'!E9 -> 60.3855 | J16: =I16*E16 -> 0
C17: Демонтаж фанеры, ДВП | D17: м2 | E17: =$A$4 -> 0 | F17: ='Прайс для расчета'!E10 -> 102.879 | G17: =F17*E17 -> 0 | I17: ='Прайс для расчета (М)'!E10 -> 51.4395 | J17: =I17*E17 -> 0
C18: Комплекс косметических демонтажных работ* | D18: м2 | E18: =$A$4 -> 0 | F18: ='Прайс для расчета'!E11 -> 1837.5 | G18: =F18*E18 -> 0 | I18: ='Прайс для расчета (М)'!E11 -> 918.75 | J18: =I18*E18 -> 0
C19: Комплекс капитальных демонтажных работ* | D19: м2 | E19: =$A$4 -> 0 | F19: ='Прайс для расчета'!E12 -> 2677.5 | G19: =F19*E19 -> 0 | I19: ='Прайс для расчета (М)'!E12 -> 1338.75 | J19: =I19*E19 -> 0
C20: Демонтаж покрытия из битумной мастики* | D20: м2 | E20: =$A$4 -> 0 | F20: ='Прайс для расчета'!E13 -> 367.5 | G20: =F20*E20 -> 0 | I20: ='Прайс для расчета (М)'!E13 -> 183.75 | J20: =I20*E20 -> 0
C21: Демонтаж деревянных полов | D21: м2 | E21: =$A$4 -> 0 | F21: ='Прайс для расчета'!E14 -> 315 | G21: =F21*E21 -> 0 | I21: ='Прайс для расчета (М)'!E14 -> 157.5 | J21: =I21*E21 -> 0
C22: Демонтаж лаг | D22: м2 | E22: =$A$4 -> 0 | F22: ='Прайс для расчета'!E15 -> 162.75 | G22: =F22*E22 -> 0 | I22: ='Прайс для расчета (М)'!E15 -> 81.375 | J22: =I22*E22 -> 0
C23: Удаление слоев из керамзита, песка | D23: м2 | E23: =$A$4 -> 0 | F23: ='Прайс для расчета'!E16 -> 162.75 | G23: =F23*E23 -> 0 | I23: ='Прайс для расчета (М)'!E16 -> 81.375 | J23: =I23*E23 -> 0
C24: Ремонт дощатых полов | D24: м2 | E24: =$A$4 -> 0 | F24: ='Прайс для расчета'!E17 -> 335.475 | G24: =F24*E24 -> 0 | I24: ='Прайс для расчета (М)'!E17 -> 167.7375 | J24: =I24*E24 -> 0
... C28: Демонтаж плитки | D28: м2 | E28: =$A$4 -> 0 | F28: ='Прайс для расчета'!E21 -> 262.5 | G28: =F28*E28 -> 0 | I28: ='Прайс для расчета (М)'!E21 -> 131.25 | J28: =I28*E28 -> 0
C29: Демонтаж бетонного бортика | D29: м/п | E29: =$A$2 -> 0 | F29: ='Прайс для расчета'!E22 -> 644.112 | G29: =F29*E29 -> 0 | I29: ='Прайс для расчета (М)'!E22 -> 322.056 | J29: =I29*E29 -> 0
C30: Демонтаж плинтуса из плитки | D30: м/п | E30: =$A$2 -> 0 | F30: ='Прайс для расчета'!E23 -> 111.825 | G30: =F30*E30 -> 0 | I30: ='Прайс для расчета (М)'!E23 -> 55.9125 | J30: =I30*E30 -> 0
C31: Демонтаж порога из плитки | D31: м/п | E31: =$A$2 -> 0 | F31: ='Прайс для расчета'!E24 -> 523.341 | G31: =F31*E31 -> 0 | I31: ='Прайс для расчета (М)'!E24 -> 261.6705 | J31: =I31*E31 -> 0
C32: Расшивка плиточных швов(пол) | D32: м2 | E32: =$A$4 -> 0 | F32: ='Прайс для расчета'!E25 -> 335.475 | G32: =F32*E32 -> 0 | I32: ='Прайс для расчета (М)'!E25 -> 167.7375 | J32: =I32*E32 -> 0
B33: =IF(SUM(B34:B59)>0,1,0) -> 0 | C33: Стены
C34: Демонтаж пластикового уголка | D34: м/п | E34: =$A$2 -> 0 | F34: ='Прайс для расчета'!E29 -> 68.586 | G34: =F34*E34 -> 0 | I34: ='Прайс для расчета (М)'!E29 -> 34.293 | J34: =I34*E34 -> 0
C35: Сверление отверстия в ГКЛ | D35: шт | E35: 1 | F35: ='Прайс для расчета'!E30 -> 231 | G35: =F35*E35 -> 231 | I35: ='Прайс для расчета (М)'!E30 -> 115.5 | J35: =I35*E35 -> 115.5
C36: Снятие обоев(стены) | D36: м2 | E36: =$A$6 -> #REF! | F36: ='Прайс для расчета'!E31 -> 210 | G36: =F36*E36 -> #REF! | I36: ='Прайс для расчета (М)'!E31 -> 105 | J36: =I36*E36 -> #REF!
C37: Снятие побелки | D37: м2 | E37: =$A$6 -> #REF! | F37: ='Прайс для расчета'!E32 -> 205.758 | G37: =F37*E37 -> #REF! | I37: ='Прайс для расчета (М)'!E32 -> 102.879 | J37: =I37*E37 -> #REF!
C38: Очистка краски со стен* | D38: м2 | E38: =$A$6 -> #REF! | F38: ='Прайс для расчета'!E33 -> 205.758 | G38: =F38*E38 -> #REF! | I38: ='Прайс для расчета (М)'!E33 -> 102.879 | J38: =I38*E38 -> #REF!
C39: Очистка масляной краски со стен* | D39: м2 | E39: =$A$6 -> #REF! | F39: ='Прайс для расчета'!E34 -> 506.94 | G39: =F39*E39 -> #REF! | I39: ='Прайс для расчета (М)'!E34 -> 253.47 | J39: =I39*E39 -> #REF!
C40: Очистка стен от "жидких" обоев | D40: м2 | E40: =$A$6 -> #REF! | F40: ='Прайс для расчета'!E35 -> 205.758 | G40: =F40*E40 -> #REF! | I40: ='Прайс для расчета (М)'!E35 -> 102.879 | J40: =I40*E40 -> #REF!
C41: Очистка стен от шпаклевки* | D41: м2 | E41: =$A$6 -> #REF! | F41: ='Прайс для расчета'!E36 -> 205.758 | G41: =F41*E41 -> #REF! | I41: ='Прайс для расчета (М)'!E36 -> 102.879 | J41: =I41*E41 -> #REF!
C42: Ошкуривание поверхности(стены) | D42: м2 | E42: =$A$6 -> #REF! | F42: ='Прайс для расчета'!E37 -> 204.75 | G42: =F42*E42 -> #REF! | I42: ='Прайс для расчета (М)'!E37 -> 102.375 | J42: =I42*E42 -> #REF!
C43: Расшивка трещин/рустов | D43: м/п | E43: =ROUND($F$7*4,0) -> #REF! | F43: ='Прайс для расчета'!E38 -> 292.236 | G43: =F43*E43 -> #REF! | I43: ='Прайс для расчета (М)'!E38 -> 146.118 | J43: =I43*E43 -> #REF!
C44: Насечка стен | D44: м2 | E44: =$A$6 -> #REF! | F44: ='Прайс для расчета'!E39 -> 164.01 | G44: =F44*E44 -> #REF! | I44: ='Прайс для расчета (М)'!E39 -> 82.005 | J44: =I44*E44 -> #REF!
...

Sheet Кухня(база)
A1: Периметр | T1: =G137 -> 0 | U1: =J137 -> 0
A2: =ROUND(D7*2+E7*2,2) -> 0 | T2: =G248 -> 0 | U2: =J248 -> 0
A3: Площадь пола | T3: =G362 -> 0 | U3: =J362 -> 0
A4: =ROUND(D7*E7,2) -> 0 | T4: 0 | U4: 0
A5: Площадь стен | C5: =#REF! -> #REF! | T5: =G373 -> 0 | U5: =J373 -> 0
A6: =ROUND(A2*F7-G7,2) -> #REF! | C6: Приложение№1 к договору №КС ____________ от ______________ 202_г. | D6: L,м/п | E6: B,м/п | F6: H,м/п | G6: Проем, м2 | T6: =G383 -> 0 | U6: =J383 -> 0
D7: 0 | E7: 0 | F7: =#REF! -> #REF! | G7: 0 | T7: =G384 -> 0 | U7: =J384 -> 0
C8: СМЕТА от "______"___________________202_г. | D8: =G386 -> #REF! | H8: Вып. | T8: =G386 -> #REF! | U8: =J386 -> 0
B10: =IF(SUM(B11:B136)>0,1,0) -> 0 | C10: Кухня. Демонтажные работы | D10: ед. изм. | E10: кол-во | F10: цена | G10: сумма | I10: цена | J10: сумма
B11: =IF(SUM(B12:B32)>0,1,0) -> 0 | C11: Полы
C12: Демонтаж плинтуса | D12: м/п | E12: =A2 -> 0 | F12: ='Прайс для расчета'!E5 -> 89.25 | G12: =F12*E12 -> 0 | I12: ='Прайс для расчета (М)'!E5 -> 44.625 | J12: =I12*E12 -> 0
C13: Демонтаж ламината, паркетной доски | D13: м2 | E13: =$A$4 -> 0 | F13: ='Прайс для расчета'!E6 -> 157.5 | G13: =F13*E13 -> 0 | I13: ='Прайс для расчета (М)'!E6 -> 78.75 | J13: =I13*E13 -> 0
C14: Демонтаж паркета штучного | D14: м2 | E14: =$A$4 -> 0 | F14: ='Прайс для расчета'!E7 -> 292.236 | G14: =F14*E14 -> 0 | I14: ='Прайс для расчета (М)'!E7 -> 146.118 | J14: =I14*E14 -> 0
C15: Демонтаж паркета шитового | D15: м2 | E15: =$A$4 -> 0 | F15: ='Прайс для расчета'!E8 -> 367.5 | G15: =F15*E15 -> 0 | I15: ='Прайс для расчета (М)'!E8 -> 183.75 | J15: =I15*E15 -> 0
C16: Демонтаж линолеума, ковролина | D16: м2 | E16: =$A$4 -> 0 | F16: ='Прайс для расчета'!E9 -> 120.771 | G16: =F16*E16 -> 0 | I16: ='Прайс для расчета (М)'!E9 -> 60.3855 | J16: =I16*E16 -> 0
C17: Демонтаж фанеры, ДВП | D17: м2 | E17: =$A$4 -> 0 | F17: ='Прайс для расчета'!E10 -> 102.879 | G17: =F17*E17 -> 0 | I17: ='Прайс для расчета (М)'!E10 -> 51.4395 | J17: =I17*E17 -> 0
C18: Комплекс косметических демонтажных работ* | D18: м2 | E18: =$A$4 -> 0 | F18: ='Прайс для расчета'!E11 -> 1837.5 | G18: =F18*E18 -> 0 | I18: ='Прайс для расчета (М)'!E11 -> 918.75 | J18: =I18*E18 -> 0
C19: Комплекс капитальных демонтажных работ* | D19: м2 | E19: =$A$4 -> 0 | F19: ='Прайс для расчета'!E12 -> 2677.5 | G19: =F19*E19 -> 0 | I19: ='Прайс для расчета (М)'!E12 -> 1338.75 | J19: =I19*E19 -> 0
C20: Демонтаж покрытия из битумной мастики* | D20: м2 | E20: =$A$4 -> 0 | F20: ='Прайс для расчета'!E13 -> 367.5 | G20: =F20*E20 -> 0 | I20: ='Прайс для расчета (М)'!E13 -> 183.75 | J20: =I20*E20 -> 0
C21: Демонтаж деревянных полов | D21: м2 | E21: =$A$4 -> 0 | F21: ='Прайс для расчета'!E14 -> 315 | G21: =F21*E21 -> 0 | I21: ='Прайс для расчета (М)'!E14 -> 157.5 | J21: =I21*E21 -> 0
C22: Демонтаж лаг | D22: м2 | E22: =$A$4 -> 0 | F22: ='Прайс для расчета'!E15 -> 162.75 | G22: =F22*E22 -> 0 | I22: ='Прайс для расчета (М)'!E15 -> 81.375 | J22: =I22*E22 -> 0
C23: Удаление слоев из керамзита, песка | D23: м2 | E23: =$A$4 -> 0 | F23: ='Прайс для расчета'!E16 -> 162.75 | G23: =F23*E23 -> 0 | I23: ='Прайс для расчета (М)'!E16 -> 81.375 | J23: =I23*E23 -> 0
C24: Ремонт дощатых полов | D24: м2 | E24: =$A$4 -> 0 | F24: ='Прайс для расчета'!E17 -> 335.475 | G24: =F24*E24 -> 0 | I24: ='Прайс для расчета (М)'!E17 -> 167.7375 | J24: =I24*E24 -> 0
... C28: Демонтаж плитки | D28: м2 | E28: =$A$4 -> 0 | F28: ='Прайс для расчета'!E21 -> 262.5 | G28: =F28*E28 -> 0 | I28: ='Прайс для расчета (М)'!E21 -> 131.25 | J28: =I28*E28 -> 0
C29: Демонтаж бетонного бортика | D29: м/п | E29: =$A$2 -> 0 | F29: ='Прайс для расчета'!E22 -> 644.112 | G29: =F29*E29 -> 0 | I29: ='Прайс для расчета (М)'!E22 -> 322.056 | J29: =I29*E29 -> 0
C30: Демонтаж плинтуса из плитки | D30: м/п | E30: =$A$2 -> 0 | F30: ='Прайс для расчета'!E23 -> 111.825 | G30: =F30*E30 -> 0 | I30: ='Прайс для расчета (М)'!E23 -> 55.9125 | J30: =I30*E30 -> 0
C31: Демонтаж порога из плитки | D31: м/п | E31: 1 | F31: ='Прайс для расчета'!E24 -> 523.341 | G31: =F31*E31 -> 523.341 | I31: ='Прайс для расчета (М)'!E24 -> 261.6705 | J31: =I31*E31 -> 261.6705
C32: Расшивка плиточных швов(пол) | D32: м2 | E32: =$A$4 -> 0 | F32: ='Прайс для расчета'!E25 -> 335.475 | G32: =F32*E32 -> 0 | I32: ='Прайс для расчета (М)'!E25 -> 167.7375 | J32: =I32*E32 -> 0
B33: =IF(SUM(B34:B59)>0,1,0) -> 0 | C33: Стены
C34: Демонтаж пластикового уголка | D34: м/п | E34: 1 | F34: ='Прайс для расчета'!E29 -> 68.586 | G34: =F34*E34 -> 68.586 | I34: ='Прайс для расчета (М)'!E29 -> 34.293 | J34: =I34*E34 -> 34.293
C35: Сверление отверстия в ГКЛ | D35: шт | E35: 1 | F35: ='Прайс для расчета'!E30 -> 231 | G35: =F35*E35 -> 231 | I35: ='Прайс для расчета (М)'!E30 -> 115.5 | J35: =I35*E35 -> 115.5
C36: Снятие обоев(стены) | D36: м2 | E36: =$A$6 -> #REF! | F36: ='Прайс для расчета'!E31 -> 210 | G36: =F36*E36 -> #REF! | I36: ='Прайс для расчета (М)'!E31 -> 105 | J36: =I36*E36 -> #REF!
C37: Снятие побелки | D37: м2 | E37: =$A$6 -> #REF! | F37: ='Прайс для расчета'!E32 -> 205.758 | G37: =F37*E37 -> #REF! | I37: ='Прайс для расчета (М)'!E32 -> 102.879 | J37: =I37*E37 -> #REF!
C38: Очистка краски со стен* | D38: м2 | E38: =$A$6 -> #REF! | F38: ='Прайс для расчета'!E33 -> 205.758 | G38: =F38*E38 -> #REF! | I38: ='Прайс для расчета (М)'!E33 -> 102.879 | J38: =I38*E38 -> #REF!
C39: Очистка масляной краски со стен* | D39: м2 | E39: =$A$6 -> #REF! | F39: ='Прайс для расчета'!E34 -> 506.94 | G39: =F39*E39 -> #REF! | I39: ='Прайс для расчета (М)'!E34 -> 253.47 | J39: =I39*E39 -> #REF!
C40: Очистка стен от "жидких" обоев | D40: м2 | E40: =$A$6 -> #REF! | F40: ='Прайс для расчета'!E35 -> 205.758 | G40: =F40*E40 -> #REF! | I40: ='Прайс для расчета (М)'!E35 -> 102.879 | J40: =I40*E40 -> #REF!
C41: Очистка стен от шпаклевки* | D41: м2 | E41: =$A$6 -> #REF! | F41: ='Прайс для расчета'!E36 -> 205.758 | G41: =F41*E41 -> #REF! | I41: ='Прайс для расчета (М)'!E36 -> 102.879 | J41: =I41*E41 -> #REF!
C42: Ошкуривание поверхности(стены) | D42: м2 | E42: =$A$6 -> #REF! | F42: ='Прайс для расчета'!E37 -> 204.75 | G42: =F42*E42 -> #REF! | I42: ='Прайс для расчета (М)'!E37 -> 102.375 | J42: =I42*E42 -> #REF!
C43: Расшивка трещин/рустов | D43: м/п | E43: 1 | F43: ='Прайс для расчета'!E38 -> 292.236 | G43: =F43*E43 -> 292.236 | I43: ='Прайс для расчета (М)'!E38 -> 146.118 | J43: =I43*E43 -> 146.118
C44: Насечка стен | D44: м2 | E44: =$A$6 -> #REF! | F44: ='Прайс для расчета'!E39 -> 164.01 | G44: =F44*E44 -> #REF! | I44: ='Прайс для расчета (М)'!E39 -> 82.005 | J44: =I44*E44 -> #REF!
...

Sheet Ванная комната(база)
A1: Периметр | T1: =G137 -> 0 | U1: =J137 -> 0
A2: =ROUND(D7*2+E7*2,2) -> 0 | T2: =G248 -> 0 | U2: =J248 -> 0
A3: Площадь пола | T3: =G382 -> 0 | U3: =J382 -> 0
A4: =ROUND(D7*E7,2) -> 0 | T4: 0 | U4: 0
A5: Площадь стен | C5: =#REF! -> #REF! | T5: =G444 -> 0 | U5: =J444 -> 0
A6: =ROUND(A2*F7-G7,2) -> #REF! | C6: Приложение№1 к договору №КС ____________ от ______________ 202_г. | D6: L,м/п | E6: B,м/п | F6: H,м/п | G6: Проем, м2 | T6: =G454 -> 0 | U6: =J454 -> 0
D7: 0 | E7: 0 | F7: =#REF! -> #REF! | G7: 0 | T7: =G455 -> 0 | U7: =J455 -> 0
C8: СМЕТА от "______"___________________202_г. | D8: =G457 -> #REF! | H8: Вып. | T8: =G457 -> #REF! | U8: =J457 -> 0
B10: =IF(SUM(B11:B136)>0,1,0) -> 0 | C10: Ванна. Демонтажные работы | D10: ед. изм. | E10: кол-во | F10: цена | G10: сумма | I10: цена | J10: сумма
B11: =IF(SUM(B12:B32)>0,1,0) -> 0 | C11: Полы
C12: Демонтаж плинтуса | D12: м/п | E12: =A2 -> 0 | F12: ='Прайс для расчета'!E5 -> 89.25 | G12: =F12*E12 -> 0 | I12: ='Прайс для расчета (М)'!E5 -> 44.625 | J12: =I12*E12 -> 0
C13: Демонтаж ламината, паркетной доски | D13: м2 | E13: =$A$4 -> 0 | F13: ='Прайс для расчета'!E6 -> 157.5 | G13: =F13*E13 -> 0 | I13: ='Прайс для расчета (М)'!E6 -> 78.75 | J13: =I13*E13 -> 0
C14: Демонтаж паркета штучного | D14: м2 | E14: =$A$4 -> 0 | F14: ='Прайс для расчета'!E7 -> 292.236 | G14: =F14*E14 -> 0 | I14: ='Прайс для расчета (М)'!E7 -> 146.118 | J14: =I14*E14 -> 0
C15: Демонтаж паркета шитового | D15: м2 | E15: =$A$4 -> 0 | F15: ='Прайс для расчета'!E8 -> 367.5 | G15: =F15*E15 -> 0 | I15: ='Прайс для расчета (М)'!E8 -> 183.75 | J15: =I15*E15 -> 0
C16: Демонтаж линолеума, ковролина | D16: м2 | E16: =$A$4 -> 0 | F16: ='Прайс для расчета'!E9 -> 120.771 | G16: =F16*E16 -> 0 | I16: ='Прайс для расчета (М)'!E9 -> 60.3855 | J16: =I16*E16 -> 0
C17: Демонтаж фанеры, ДВП | D17: м2 | E17: =$A$4 -> 0 | F17: ='Прайс для расчета'!E10 -> 102.879 | G17: =F17*E17 -> 0 | I17: ='Прайс для расчета (М)'!E10 -> 51.4395 | J17: =I17*E17 -> 0
C18: Комплекс косметических демонтажных работ* | D18: м2 | E18: =$A$4 -> 0 | F18: ='Прайс для расчета'!E11 -> 1837.5 | G18: =F18*E18 -> 0 | I18: ='Прайс для расчета (М)'!E11 -> 918.75 | J18: =I18*E18 -> 0
C19: Комплекс капитальных демонтажных работ* | D19: м2 | E19: =$A$4 -> 0 | F19: ='Прайс для расчета'!E12 -> 2677.5 | G19: =F19*E19 -> 0 | I19: ='Прайс для расчета (М)'!E12 -> 1338.75 | J19: =I19*E19 -> 0
C20: Демонтаж покрытия из битумной мастики* | D20: м2 | E20: =$A$4 -> 0 | F20: ='Прайс для расчета'!E13 -> 367.5 | G20: =F20*E20 -> 0 | I20: ='Прайс для расчета (М)'!E13 -> 183.75 | J20: =I20*E20 -> 0
C21: Демонтаж деревянных полов | D21: м2 | E21: =$A$4 -> 0 | F21: ='Прайс для расчета'!E14 -> 315 | G21: =F21*E21 -> 0 | I21: ='Прайс для расчета (М)'!E14 -> 157.5 | J21: =I21*E21 -> 0
C22: Демонтаж лаг | D22: м2 | E22: =$A$4 -> 0 | F22: ='Прайс для расчета'!E15 -> 162.75 | G22: =F22*E22 -> 0 | I22: ='Прайс для расчета (М)'!E15 -> 81.375 | J22: =I22*E22 -> 0
C23: Удаление слоев из керамзита, песка | D23: м2 | E23: =$A$4 -> 0 | F23: ='Прайс для расчета'!E16 -> 162.75 | G23: =F23*E23 -> 0 | I23: ='Прайс для расчета (М)'!E16 -> 81.375 | J23: =I23*E23 -> 0
C24: Ремонт дощатых полов | D24: м2 | E24: =$A$4 -> 0 | F24: ='Прайс для расчета'!E17 -> 335.475 | G24: =F24*E24 -> 0 | I24: ='Прайс для расчета (М)'!E17 -> 167.7375 | J24: =I24*E24 -> 0
... C28: Демонтаж плитки | D28: м2 | E28: =$A$4 -> 0 | F28: ='Прайс для расчета'!E21 -> 262.5 | G28: =F28*E28 -> 0 | I28: ='Прайс для расчета (М)'!E21 -> 131.25 | J28: =I28*E28 -> 0
C29: Демонтаж бетонного бортика | D29: м/п | E29: =$A$2 -> 0 | F29: ='Прайс для расчета'!E22 -> 644.112 | G29: =F29*E29 -> 0 | I29: ='Прайс для расчета (М)'!E22 -> 322.056 | J29: =I29*E29 -> 0
C30: Демонтаж плинтуса из плитки | D30: м/п | E30: =$A$2 -> 0 | F30: ='Прайс для расчета'!E23 -> 111.825 | G30: =F30*E30 -> 0 | I30: ='Прайс для расчета (М)'!E23 -> 55.9125 | J30: =I30*E30 -> 0
C31: Демонтаж порога из плитки | D31: м/п | E31: 1 | F31: ='Прайс для расчета'!E24 -> 523.341 | G31: =F31*E31 -> 523.341 | I31: ='Прайс для расчета (М)'!E24 -> 261.6705 | J31: =I31*E31 -> 261.6705
C32: Расшивка плиточных швов(пол) | D32: м2 | E32: =$A$4 -> 0 | F32: ='Прайс для расчета'!E25 -> 335.475 | G32: =F32*E32 -> 0 | I32: ='Прайс для расчета (М)'!E25 -> 167.7375 | J32: =I32*E32 -> 0
B33: =IF(SUM(B34:B59)>0,1,0) -> 0 | C33: Стены
C34: Демонтаж пластикового уголка | D34: м/п | E34: 1 | F34: ='Прайс для расчета'!E29 -> 68.586 | G34: =F34*E34 -> 68.586 | I34: ='Прайс для расчета (М)'!E29 -> 34.293 | J34: =I34*E34 -> 34.293
C35: Сверление отверстия в ГКЛ | D35: шт | E35: 1 | F35: ='Прайс для расчета'!E30 -> 231 | G35: =F35*E35 -> 231 | I35: ='Прайс для расчета (М)'!E30 -> 115.5 | J35: =I35*E35 -> 115.5
C36: Снятие обоев(стены) | D36: м2 | E36: =$A$6 -> #REF! | F36: ='Прайс для расчета'!E31 -> 210 | G36: =F36*E36 -> #REF! | I36: ='Прайс для расчета (М)'!E31 -> 105 | J36: =I36*E36 -> #REF!
C37: Снятие побелки | D37: м2 | E37: =$A$6 -> #REF! | F37: ='Прайс для расчета'!E32 -> 205.758 | G37: =F37*E37 -> #REF! | I37: ='Прайс для расчета (М)'!E32 -> 102.879 | J37: =I37*E37 -> #REF!
C38: Очистка краски со стен* | D38: м2 | E38: =$A$6 -> #REF! | F38: ='Прайс для расчета'!E33 -> 205.758 | G38: =F38*E38 -> #REF! | I38: ='Прайс для расчета (М)'!E33 -> 102.879 | J38: =I38*E38 -> #REF!
C39: Очистка масляной краски со стен* | D39: м2 | E39: =$A$6 -> #REF! | F39: ='Прайс для расчета'!E34 -> 506.94 | G39: =F39*E39 -> #REF! | I39: ='Прайс для расчета (М)'!E34 -> 253.47 | J39: =I39*E39 -> #REF!
C40: Очистка стен от "жидких" обоев | D40: м2 | E40: =$A$6 -> #REF! | F40: ='Прайс для расчета'!E35 -> 205.758 | G40: =F40*E40 -> #REF! | I40: ='Прайс для расчета (М)'!E35 -> 102.879 | J40: =I40*E40 -> #REF!
C41: Очистка стен от шпаклевки* | D41: м2 | E41: =$A$6 -> #REF! | F41: ='Прайс для расчета'!E36 -> 205.758 | G41: =F41*E41 -> #REF! | I41: ='Прайс для расчета (М)'!E36 -> 102.879 | J41: =I41*E41 -> #REF!
C42: Ошкуривание поверхности(стены) | D42: м2 | E42: =$A$6 -> #REF! | F42: ='Прайс для расчета'!E37 -> 204.75 | G42: =F42*E42 -> #REF! | I42: ='Прайс для расчета (М)'!E37 -> 102.375 | J42: =I42*E42 -> #REF!
C43: Расшивка трещин/рустов | D43: м/п | E43: 1 | F43: ='Прайс для расчета'!E38 -> 292.236 | G43: =F43*E43 -> 292.236 | I43: ='Прайс для расчета (М)'!E38 -> 146.118 | J43: =I43*E43 -> 146.118
C44: Насечка стен | D44: м2 | E44: =$A$6 -> #REF! | F44: ='Прайс для расчета'!E39 -> 164.01 | G44: =F44*E44 -> #REF! | I44: ='Прайс для расчета (М)'!E39 -> 82.005 | J44: =I44*E44 -> #REF!
...

Sheet Туалет(база)
A1: Периметр | T1: =G137 -> 0 | U1: =J137 -> 0
A2: =ROUND(D7*2+E7*2,2) -> 0 | T2: =G248 -> 0 | U2: =J248 -> 0
A3: Площадь пола | T3: =G382 -> 0 | U3: =J382 -> 0
A4: =ROUND(D7*E7,2) -> 0 | T4: 0 | U4: 0
A5: Площадь стен | C5: =#REF! -> #REF! | T5: =G444 -> 0 | U5: =J444 -> 0
A6: =ROUND(A2*F7-G7,2) -> #REF! | C6: Приложение№1 к договору №КС ____________ от ______________ 202_г. | D6: L,м/п | E6: B,м/п | F6: H,м/п | G6: Проем, м2 | T6: =G454 -> 0 | U6: =J454 -> 0
D7: 0 | E7: 0 | F7: =#REF! -> #REF! | G7: 0 | T7: =G455 -> 0 | U7: =J455 -> 0
C8: СМЕТА от "______"___________________202_г. | D8: =G457 -> #REF! | H8: Вып. | T8: =G457 -> #REF! | U8: =J457 -> 0
U9: =J448 -> 1285.9875
B10: =IF(SUM(B11:B136)>0,1,0) -> 0 | C10: Туалет. Демонтажные работы | D10: ед. изм. | E10: кол-во | F10: цена | G10: сумма | I10: цена | J10: сумма | U10: =J458 -> 0
B11: =IF(SUM(B12:B32)>0,1,0) -> 0 | C11: Полы | U11: =J459 -> 0
C12: Демонтаж плинтуса | D12: м/п | E12: =A2 -> 0 | F12: ='Прайс для расчета'!E5 -> 89.25 | G12: =F12*E12 -> 0 | I12: ='Прайс для расчета (М)'!E5 -> 44.625 | J12: =I12*E12 -> 0 | U12: =J461 -> 0
C13: Демонтаж ламината, паркетной доски | D13: м2 | E13: =$A$4 -> 0 | F13: ='Прайс для расчета'!E6 -> 157.5 | G13: =F13*E13 -> 0 | I13: ='Прайс для расчета (М)'!E6 -> 78.75 | J13: =I13*E13 -> 0
C14: Демонтаж паркета штучного | D14: м2 | E14: =$A$4 -> 0 | F14: ='Прайс для расчета'!E7 -> 292.236 | G14: =F14*E14 -> 0 | I14: ='Прайс для расчета (М)'!E7 -> 146.118 | J14: =I14*E14 -> 0
C15: Демонтаж паркета шитового | D15: м2 | E15: =$A$4 -> 0 | F15: ='Прайс для расчета'!E8 -> 367.5 | G15: =F15*E15 -> 0 | I15: ='Прайс для расчета (М)'!E8 -> 183.75 | J15: =I15*E15 -> 0
C16: Демонтаж линолеума, ковролина | D16: м2 | E16: =$A$4 -> 0 | F16: ='Прайс для расчета'!E9 -> 120.771 | G16: =F16*E16 -> 0 | I16: ='Прайс для расчета (М)'!E9 -> 60.3855 | J16: =I16*E16 -> 0
C17: Демонтаж фанеры, ДВП | D17: м2 | E17: =$A$4 -> 0 | F17: ='Прайс для расчета'!E10 -> 102.879 | G17: =F17*E17 -> 0 | I17: ='Прайс для расчета (М)'!E10 -> 51.4395 | J17: =I17*E17 -> 0
C18: Комплекс косметических демонтажных работ* | D18: м2 | E18: =$A$4 -> 0 | F18: ='Прайс для расчета'!E11 -> 1837.5 | G18: =F18*E18 -> 0 | I18: ='Прайс для расчета (М)'!E11 -> 918.75 | J18: =I18*E18 -> 0
C19: Комплекс капитальных демонтажных работ* | D19: м2 | E19: =$A$4 -> 0 | F19: ='Прайс для расчета'!E12 -> 2677.5 | G19: =F19*E19 -> 0 | I19: ='Прайс для расчета (М)'!E12 -> 1338.75 | J19: =I19*E19 -> 0
C20: Демонтаж покрытия из битумной мастики* | D20: м2 | E20: =$A$4 -> 0 | F20: ='Прайс для расчета'!E13 -> 367.5 | G20: =F20*E20 -> 0 | I20: ='Прайс для расчета (М)'!E13 -> 183.75 | J20: =I20*E20 -> 0
C21: Демонтаж деревянных полов | D21: м2 | E21: =$A$4 -> 0 | F21: ='Прайс для расчета'!E14 -> 315 | G21: =F21*E21 -> 0 | I21: ='Прайс для расчета (М)'!E14 -> 157.5 | J21: =I21*E21 -> 0
C22: Демонтаж лаг | D22: м2 | E22: =$A$4 -> 0 | F22: ='Прайс для расчета'!E15 -> 162.75 | G22: =F22*E22 -> 0 | I22: ='Прайс для расчета (М)'!E15 -> 81.375 | J22: =I22*E22 -> 0
C23: Удаление слоев из керамзита, песка | D23: м2 | E23: =$A$4 -> 0 | F23: ='Прайс для расчета'!E16 -> 162.75 | G23: =F23*E23 -> 0 | I23: ='Прайс для расчета (М)'!E16 -> 81.375 | J23: =I23*E23 -> 0
C24: Ремонт дощатых полов | D24: м2 | E24: =$A$4 -> 0 | F24: ='Прайс для расчета'!E17 -> 335.475 | G24: =F24*E24 -> 0 | I24: ='Прайс для расчета (М)'!E17 -> 167.7375 | J24: =I24*E24 -> 0
... C28: Демонтаж плитки | D28: м2 | E28: =$A$4 -> 0 | F28: ='Прайс для расчета'!E21 -> 262.5 | G28: =F28*E28 -> 0 | I28: ='Прайс для расчета (М)'!E21 -> 131.25 | J28: =I28*E28 -> 0
C29: Демонтаж бетонного бортика | D29: м/п | E29: =$A$2 -> 0 | F29: ='Прайс для расчета'!E22 -> 644.112 | G29: =F29*E29 -> 0 | I29: ='Прайс для расчета (М)'!E22 -> 322.056 | J29: =I29*E29 -> 0
C30: Демонтаж плинтуса из плитки | D30: м/п | E30: =$A$2 -> 0 | F30: ='Прайс для расчета'!E23 -> 111.825 | G30: =F30*E30 -> 0 | I30: ='Прайс для расчета (М)'!E23 -> 55.9125 | J30: =I30*E30 -> 0
C31: Демонтаж порога из плитки | D31: м/п | E31: 1 | F31: ='Прайс для расчета'!E24 -> 523.341 | G31: =F31*E31 -> 523.341 | I31: ='Прайс для расчета (М)'!E24 -> 261.6705 | J31: =I31*E31 -> 261.6705
C32: Расшивка плиточных швов(пол) | D32: м2 | E32: =$A$4 -> 0 | F32: ='Прайс для расчета'!E25 -> 335.475 | G32: =F32*E32 -> 0 | I32: ='Прайс для расчета (М)'!E25 -> 167.7375 | J32: =I32*E32 -> 0
B33: =IF(SUM(B34:B59)>0,1,0) -> 0 | C33: Стены
C34: Демонтаж пластикового уголка | D34: м/п | E34: 1 | F34: ='Прайс для расчета'!E29 -> 68.586 | G34: =F34*E34 -> 68.586 | I34: ='Прайс для расчета (М)'!E29 -> 34.293 | J34: =I34*E34 -> 34.293
C35: Сверление отверстия в ГКЛ | D35: шт | E35: 1 | F35: ='Прайс для расчета'!E30 -> 231 | G35: =F35*E35 -> 231 | I35: ='Прайс для расчета (М)'!E30 -> 115.5 | J35: =I35*E35 -> 115.5
C36: Снятие обоев(стены) | D36: м2 | E36: =$A$6 -> #REF! | F36: ='Прайс для расчета'!E31 -> 210 | G36: =F36*E36 -> #REF! | I36: ='Прайс для расчета (М)'!E31 -> 105 | J36: =I36*E36 -> #REF!
C37: Снятие побелки | D37: м2 | E37: =$A$6 -> #REF! | F37: ='Прайс для расчета'!E32 -> 205.758 | G37: =F37*E37 -> #REF! | I37: ='Прайс для расчета (М)'!E32 -> 102.879 | J37: =I37*E37 -> #REF!
C38: Очистка краски со стен* | D38: м2 | E38: =$A$6 -> #REF! | F38: ='Прайс для расчета'!E33 -> 205.758 | G38: =F38*E38 -> #REF! | I38: ='Прайс для расчета (М)'!E33 -> 102.879 | J38: =I38*E38 -> #REF!
C39: Очистка масляной краски со стен* | D39: м2 | E39: =$A$6 -> #REF! | F39: ='Прайс для расчета'!E34 -> 506.94 | G39: =F39*E39 -> #REF! | I39: ='Прайс для расчета (М)'!E34 -> 253.47 | J39: =I39*E39 -> #REF!
C40: Очистка стен от "жидких" обоев | D40: м2 | E40: =$A$6 -> #REF! | F40: ='Прайс для расчета'!E35 -> 205.758 | G40: =F40*E40 -> #REF! | I40: ='Прайс для расчета (М)'!E35 -> 102.879 | J40: =I40*E40 -> #REF!
C41: Очистка стен от шпаклевки* | D41: м2 | E41: =$A$6 -> #REF! | F41: ='Прайс для расчета'!E36 -> 205.758 | G41: =F41*E41 -> #REF! | I41: ='Прайс для расчета (М)'!E36 -> 102.879 | J41: =I41*E41 -> #REF!
C42: Ошкуривание поверхности(стены) | D42: м2 | E42: =$A$6 -> #REF! | F42: ='Прайс для расчета'!E37 -> 204.75 | G42: =F42*E42 -> #REF! | I42: ='Прайс для расчета (М)'!E37 -> 102.375 | J42: =I42*E42 -> #REF!
C43: Расшивка трещин/рустов | D43: м/п | E43: 1 | F43: ='Прайс для расчета'!E38 -> 292.236 | G43: =F43*E43 -> 292.236 | I43: ='Прайс для расчета (М)'!E38 -> 146.118 | J43: =I43*E43 -> 146.118
...

Sheet Коридор(база)
A1: Периметр | T1: =G137 -> 0 | U1: =J137 -> 0
A2: =ROUND(D7*2+E7*2,2) -> 0 | T2: =G248 -> 0 | U2: =J248 -> 0
A3: Площадь пола | T3: =G362 -> 0 | U3: =J362 -> 0
A4: =ROUND(D7*E7,2) -> 0 | T4: 0 | U4: 0
A5: Площадь стен | C5: =#REF! -> #REF! | T5: 0 | U5: 0
A6: =ROUND(A2*F7-G7,2) -> #REF! | C6: Приложение№1 к договору №КС ____________ от ______________ 202_г. | D6: L,м/п | E6: B,м/п | F6: H,м/п | G6: Проем, м2 | I6: H,м/п | J6: Проем, м2 | T6: =G372 -> 0 | U6: =J372 -> 0
D7: 0 | E7: 0 | F7: =#REF! -> #REF! | G7: 0 | I7: =#REF! -> #REF! | J7: 0 | T7: =G373 -> 0 | U7: =J373 -> 0
C8: СМЕТА от "______"___________________202_г. | D8: =G375 -> #REF! | H8: Вып. | T8: =G375 -> #REF! | U8: =J375 -> 0
B10: =IF(SUM(B11:B136)>0,1,0) -> 0 | C10: Коридор. Демонтажные работы | D10: ед. изм. | E10: кол-во | F10: цена | G10: сумма | I10: цена | J10: сумма
B11: =IF(SUM(B12:B32)>0,1,0) -> 0 | C11: Полы
C12: Демонтаж плинтуса | D12: м/п | E12: =$A$2 -> 0 | F12: ='Прайс для расчета'!E5 -> 89.25 | G12: =F12*E12 -> 0 | I12: ='Прайс для расчета (М)'!E5 -> 44.625 | J12: =I12*E12 -> 0
C13: Демонтаж ламината, паркетной доски | D13: м2 | E13: =$A$4 -> 0 | F13: ='Прайс для расчета'!E6 -> 157.5 | G13: =F13*E13 -> 0 | I13: ='Прайс для расчета (М)'!E6 -> 78.75 | J13: =I13*E13 -> 0
C14: Демонтаж паркета штучного | D14: м2 | E14: =$A$4 -> 0 | F14: ='Прайс для расчета'!E7 -> 292.236 | G14: =F14*E14 -> 0 | I14: ='Прайс для расчета (М)'!E7 -> 146.118 | J14: =I14*E14 -> 0
C15: Демонтаж паркета шитового | D15: м2 | E15: =$A$4 -> 0 | F15: ='Прайс для расчета'!E8 -> 367.5 | G15: =F15*E15 -> 0 | I15: ='Прайс для расчета (М)'!E8 -> 183.75 | J15: =I15*E15 -> 0
C16: Демонтаж линолеума, ковролина | D16: м2 | E16: =$A$4 -> 0 | F16: ='Прайс для расчета'!E9 -> 120.771 | G16: =F16*E16 -> 0 | I16: ='Прайс для расчета (М)'!E9 -> 60.3855 | J16: =I16*E16 -> 0
C17: Демонтаж фанеры, ДВП | D17: м2 | E17: =$A$4 -> 0 | F17: ='Прайс для расчета'!E10 -> 102.879 | G17: =F17*E17 -> 0 | I17: ='Прайс для расчета (М)'!E10 -> 51.4395 | J17: =I17*E17 -> 0
C18: Комплекс косметических демонтажных работ* | D18: м2 | E18: =$A$4 -> 0 | F18: ='Прайс для расчета'!E11 -> 1837.5 | G18: =F18*E18 -> 0 | I18: ='Прайс для расчета (М)'!E11 -> 918.75 | J18: =I18*E18 -> 0
C19: Комплекс капитальных демонтажных работ* | D19: м2 | E19: =$A$4 -> 0 | F19: ='Прайс для расчета'!E12 -> 2677.5 | G19: =F19*E19 -> 0 | I19: ='Прайс для расчета (М)'!E12 -> 1338.75 | J19: =I19*E19 -> 0
C20: Демонтаж покрытия из битумной мастики* | D20: м2 | E20: =$A$4 -> 0 | F20: ='Прайс для расчета'!E13 -> 367.5 | G20: =F20*E20 -> 0 | I20: ='Прайс для расчета (М)'!E13 -> 183.75 | J20: =I20*E20 -> 0
C21: Демонтаж деревянных полов | D21: м2 | E21: =$A$4 -> 0 | F21: ='Прайс для расчета'!E14 -> 315 | G21: =F21*E21 -> 0 | I21: ='Прайс для расчета (М)'!E14 -> 157.5 | J21: =I21*E21 -> 0
C22: Демонтаж лаг | D22: м2 | E22: =$A$4 -> 0 | F22: ='Прайс для расчета'!E15 -> 162.75 | G22: =F22*E22 -> 0 | I22: ='Прайс для расчета (М)'!E15 -> 81.375 | J22: =I22*E22 -> 0
C23: Удаление слоев из керамзита, песка | D23: м2 | E23: =$A$4 -> 0 | F23: ='Прайс для расчета'!E16 -> 162.75 | G23: =F23*E23 -> 0 | I23: ='Прайс для расчета (М)'!E16 -> 81.375 | J23: =I23*E23 -> 0
C24: Ремонт дощатых полов | D24: м2 | E24: =$A$4 -> 0 | F24: ='Прайс для расчета'!E17 -> 335.475 | G24: =F24*E24 -> 0 | I24: ='Прайс для расчета (М)'!E17 -> 167.7375 | J24: =I24*E24 -> 0
... C28: Демонтаж плитки | D28: м2 | E28: =$A$4 -> 0 | F28: ='Прайс для расчета'!E21 -> 262.5 | G28: =F28*E28 -> 0 | I28: ='Прайс для расчета (М)'!E21 -> 131.25 | J28: =I28*E28 -> 0
C29: Демонтаж бетонного бортика | D29: м/п | E29: =$A$2 -> 0 | F29: ='Прайс для расчета'!E22 -> 644.112 | G29: =F29*E29 -> 0 | I29: ='Прайс для расчета (М)'!E22 -> 322.056 | J29: =I29*E29 -> 0
C30: Демонтаж плинтуса из плитки | D30: м/п | E30: =$A$2 -> 0 | F30: ='Прайс для расчета'!E23 -> 111.825 | G30: =F30*E30 -> 0 | I30: ='Прайс для расчета (М)'!E23 -> 55.9125 | J30: =I30*E30 -> 0
C31: Демонтаж порога из плитки | D31: м/п | E31: 1 | F31: ='Прайс для расчета'!E24 -> 523.341 | G31: =F31*E31 -> 523.341 | I31: ='Прайс для расчета (М)'!E24 -> 261.6705 | J31: =I31*E31 -> 261.6705
C32: Расшивка плиточных швов(пол) | D32: м2 | E32: =$A$4 -> 0 | F32: ='Прайс для расчета'!E25 -> 335.475 | G32: =F32*E32 -> 0 | I32: ='Прайс для расчета (М)'!E25 -> 167.7375 | J32: =I32*E32 -> 0
B33: =IF(SUM(B34:B59)>0,1,0) -> 0 | C33: Стены
C34: Демонтаж пластикового уголка | D34: м/п | E34: 1 | F34: ='Прайс для расчета'!E29 -> 68.586 | G34: =F34*E34 -> 68.586 | I34: ='Прайс для расчета (М)'!E29 -> 34.293 | J34: =I34*E34 -> 34.293
C35: Сверление отверстия в ГКЛ | D35: шт | E35: 1 | F35: ='Прайс для расчета'!E30 -> 231 | G35: =F35*E35 -> 231 | I35: ='Прайс для расчета (М)'!E30 -> 115.5 | J35: =I35*E35 -> 115.5
C36: Снятие обоев(стены) | D36: м2 | E36: =$A$6 -> #REF! | F36: ='Прайс для расчета'!E31 -> 210 | G36: =F36*E36 -> #REF! | I36: ='Прайс для расчета (М)'!E31 -> 105 | J36: =I36*E36 -> #REF!
C37: Снятие побелки | D37: м2 | E37: =$A$6 -> #REF! | F37: ='Прайс для расчета'!E32 -> 205.758 | G37: =F37*E37 -> #REF! | I37: ='Прайс для расчета (М)'!E32 -> 102.879 | J37: =I37*E37 -> #REF!
C38: Очистка краски со стен* | D38: м2 | E38: =$A$6 -> #REF! | F38: ='Прайс для расчета'!E33 -> 205.758 | G38: =F38*E38 -> #REF! | I38: ='Прайс для расчета (М)'!E33 -> 102.879 | J38: =I38*E38 -> #REF!
C39: Очистка масляной краски со стен* | D39: м2 | E39: =$A$6 -> #REF! | F39: ='Прайс для расчета'!E34 -> 506.94 | G39: =F39*E39 -> #REF! | I39: ='Прайс для расчета (М)'!E34 -> 253.47 | J39: =I39*E39 -> #REF!
C40: Очистка стен от "жидких" обоев | D40: м2 | E40: =$A$6 -> #REF! | F40: ='Прайс для расчета'!E35 -> 205.758 | G40: =F40*E40 -> #REF! | I40: ='Прайс для расчета (М)'!E35 -> 102.879 | J40: =I40*E40 -> #REF!
C41: Очистка стен от шпаклевки* | D41: м2 | E41: =$A$6 -> #REF! | F41: ='Прайс для расчета'!E36 -> 205.758 | G41: =F41*E41 -> #REF! | I41: ='Прайс для расчета (М)'!E36 -> 102.879 | J41: =I41*E41 -> #REF!
C42: Ошкуривание поверхности(стены) | D42: м2 | E42: =$A$6 -> #REF! | F42: ='Прайс для расчета'!E37 -> 204.75 | G42: =F42*E42 -> #REF! | I42: ='Прайс для расчета (М)'!E37 -> 102.375 | J42: =I42*E42 -> #REF!
C43: Расшивка трещин/рустов | D43: м/п | E43: 1 | F43: ='Прайс для расчета'!E38 -> 292.236 | G43: =F43*E43 -> 292.236 | I43: ='Прайс для расчета (М)'!E38 -> 146.118 | J43: =I43*E43 -> 146.118
C44: Насечка стен | D44: м2 | E44: =$A$6 -> #REF! | F44: ='Прайс для расчета'!E39 -> 164.01 | G44: =F44*E44 -> #REF! | I44: ='Прайс для расчета (М)'!E39 -> 82.005 | J44: =I44*E44 -> #REF!
...

Sheet Смета по коридору №1
A1: Периметр | T1: =G137 -> 10000 | U1: =J137 -> 167.7375
A2: 10.32 | T2: =G248 -> #REF! | U2: =J248 -> #REF!
A3: Площадь пола | T3: =G362 -> 51500.4 | U3: =J362 -> 25287.57
A4: 7.76 | D4: Прихожая | T4: 0 | U4: 0
A5: Площадь стен | C5: =#REF! -> #REF! | T5: 0 | U5: 0
A6: =ROUND(A2*F7-G7,2) -> #REF! | C6: Приложение№1 к договору №КС ____________ от ______________ 202_г. | D6: L,м/п | E6: B,м/п | F6: H,м/п | G6: Проем, м2 | I6: H,м/п | J6: Проем, м2 | T6: =G372 -> 855.54 | U6: =J372 -> 427.77
D7: 0 | E7: 0 | F7: =#REF! -> #REF! | G7: 5.6 | I7: =#REF! -> #REF! | J7: 0 | T7: =G373 -> #REF! | U7: =J373 -> #REF!
C8: СМЕТА от "______"___________________202_г. | D8: =G375 -> #REF! | H8: Вып. | T8: =G375 -> #REF! | U8: =J375 -> #REF!
B10: =IF(SUM(B11:B136)>0,1,0) -> 1 | C10: Коридор 1. Демонтажные работы | D10: ед. изм. | E10: кол-во | F10: цена | G10: сумма | I10: цена | J10: сумма
B11: =IF(SUM(B12:B32)>0,1,0) -> 0 | C11: Полы
C12: Демонтаж плинтуса | D12: м/п | E12: =$A$2 -> 10.32 | F12: ='Прайс для расчета'!E5 -> 89.25 | G12: =F12*E12 -> 921.06 | I12: ='Прайс для расчета (М)'!E5 -> 44.625 | J12: =I12*E12 -> 460.53
C13: Демонтаж ламината, паркетной доски | D13: м2 | E13: =$A$4 -> 7.76 | F13: ='Прайс для расчета'!E6 -> 157.5 | G13: =F13*E13 -> 1222.2 | I13: ='Прайс для расчета (М)'!E6 -> 78.75 | J13: =I13*E13 -> 611.1
C14: Демонтаж паркета штучного | D14: м2 | E14: =$A$4 -> 7.76 | F14: ='Прайс для расчета'!E7 -> 292.236 | G14: =F14*E14 -> 2267.7514 | I14: ='Прайс для расчета (М)'!E7 -> 146.118 | J14: =I14*E14 -> 1133.8757
C15: Демонтаж паркета шитового | D15: м2 | E15: =$A$4 -> 7.76 | F15: ='Прайс для расчета'!E8 -> 367.5 | G15: =F15*E15 -> 2851.8 | I15: ='Прайс для расчета (М)'!E8 -> 183.75 | J15: =I15*E15 -> 1425.9
C16: Демонтаж линолеума, ковролина | D16: м2 | E16: =$A$4 -> 7.76 | F16: ='Прайс для расчета'!E9 -> 120.771 | G16: =F16*E16 -> 937.18296 | I16: ='Прайс для расчета (М)'!E9 -> 60.3855 | J16: =I16*E16 -> 468.59148
C17: Демонтаж фанеры, ДВП | D17: м2 | E17: =$A$4 -> 7.76 | F17: ='Прайс для расчета'!E10 -> 102.879 | G17: =F17*E17 -> 798.34104 | I17: ='Прайс для расчета (М)'!E10 -> 51.4395 | J17: =I17*E17 -> 399.17052
C18: Комплекс косметических демонтажных работ* | D18: м2 | E18: =$A$4 -> 7.76 | F18: ='Прайс для расчета'!E11 -> 1837.5 | G18: =F18*E18 -> 14259 | I18: ='Прайс для расчета (М)'!E11 -> 918.75 | J18: =I18*E18 -> 7129.5
C19: Комплекс капитальных демонтажных работ* | D19: м2 | E19: =$A$4 -> 7.76 | F19: ='Прайс для расчета'!E12 -> 2677.5 | G19: =F19*E19 -> 20777.4 | I19: ='Прайс для расчета (М)'!E12 -> 1338.75 | J19: =I19*E19 -> 10388.7
C20: Демонтаж покрытия из битумной мастики* | D20: м2 | E20: =$A$4 -> 7.76 | F20: ='Прайс для расчета'!E13 -> 367.5 | G20: =F20*E20 -> 2851.8 | I20: ='Прайс для расчета (М)'!E13 -> 183.75 | J20: =I20*E20 -> 1425.9
C21: Демонтаж деревянных полов | D21: м2 | E21: =$A$4 -> 7.76 | F21: ='Прайс для расчета'!E14 -> 315 | G21: =F21*E21 -> 2444.4 | I21: ='Прайс для расчета (М)'!E14 -> 157.5 | J21: =I21*E21 -> 1222.2
C22: Демонтаж лаг | D22: м2 | E22: =$A$4 -> 7.76 | F22: ='Прайс для расчета'!E15 -> 162.75 | G22: =F22*E22 -> 1262.94 | I22: ='Прайс для расчета (М)'!E15 -> 81.375 | J22: =I22*E22 -> 631.47
C23: Удаление слоев из керамзита, песка | D23: м2 | E23: =$A$4 -> 7.76 | F23: ='Прайс для расчета'!E16 -> 162.75 | G23: =F23*E23 -> 1262.94 | I23: ='Прайс для расчета (М)'!E16 -> 81.375 | J23: =I23*E23 -> 631.47
C24: Ремонт дощатых полов | D24: м2 | E24: =$A$4 -> 7.76 | F24: ='Прайс для расчета'!E17 -> 335.475 | G24: =F24*E24 -> 2603.286 | I24: ='Прайс для расчета (М)'!E17 -> 167.7375 | J24: =I24*E24 -> 1301.643
... C28: Демонтаж плитки | D28: м2 | E28: =$A$4 -> 7.76 | F28: ='Прайс для расчета'!E21 -> 262.5 | G28: =F28*E28 -> 2037 | I28: ='Прайс для расчета (М)'!E21 -> 131.25 | J28: =I28*E28 -> 1018.5
C29: Демонтаж бетонного бортика | D29: м/п | E29: =$A$2 -> 10.32 | F29: ='Прайс для расчета'!E22 -> 644.112 | G29: =F29*E29 -> 6647.2358 | I29: ='Прайс для расчета (М)'!E22 -> 322.056 | J29: =I29*E29 -> 3323.6179
C30: Демонтаж плинтуса из плитки | D30: м/п | E30: =$A$2 -> 10.32 | F30: ='Прайс для расчета'!E23 -> 111.825 | G30: =F30*E30 -> 1154.034 | I30: ='Прайс для расчета (М)'!E23 -> 55.9125 | J30: =I30*E30 -> 577.017
C31: Демонтаж порога из плитки | D31: м/п | E31: 1 | F31: ='Прайс для расчета'!E24 -> 523.341 | G31: =F31*E31 -> 523.341 | I31: ='Прайс для расчета (М)'!E24 -> 261.6705 | J31: =I31*E31 -> 261.6705
C32: Расшивка плиточных швов(пол) | D32: м2 | E32: =$A$4 -> 7.76 | F32: ='Прайс для расчета'!E25 -> 335.475 | G32: =F32*E32 -> 2603.286 | I32: ='Прайс для расчета (М)'!E25 -> 167.7375 | J32: =I32*E32 -> 1301.643
B33: =IF(SUM(B34:B59)>0,1,0) -> 0 | C33: Стены
C34: Демонтаж пластикового уголка | D34: м/п | E34: 1 | F34: ='Прайс для расчета'!E29 -> 68.586 | G34: =F34*E34 -> 68.586 | I34: ='Прайс для расчета (М)'!E29 -> 34.293 | J34: =I34*E34 -> 34.293
C35: Сверление отверстия в ГКЛ | D35: шт | E35: 1 | F35: ='Прайс для расчета'!E30 -> 231 | G35: =F35*E35 -> 231 | I35: ='Прайс для расчета (М)'!E30 -> 115.5 | J35: =I35*E35 -> 115.5
C36: Снятие обоев(стены) | D36: м2 | E36: =$A$6 -> #REF! | F36: ='Прайс для расчета'!E31 -> 210 | G36: =F36*E36 -> #REF! | I36: ='Прайс для расчета (М)'!E31 -> 105 | J36: =I36*E36 -> #REF!
C37: Снятие побелки | D37: м2 | E37: =$A$6 -> #REF! | F37: ='Прайс для расчета'!E32 -> 205.758 | G37: =F37*E37 -> #REF! | I37: ='Прайс для расчета (М)'!E32 -> 102.879 | J37: =I37*E37 -> #REF!
C38: Очистка краски со стен* | D38: м2 | E38: =$A$6 -> #REF! | F38: ='Прайс для расчета'!E33 -> 205.758 | G38: =F38*E38 -> #REF! | I38: ='Прайс для расчета (М)'!E33 -> 102.879 | J38: =I38*E38 -> #REF!
C39: Очистка масляной краски со стен* | D39: м2 | E39: =$A$6 -> #REF! | F39: ='Прайс для расчета'!E34 -> 506.94 | G39: =F39*E39 -> #REF! | I39: ='Прайс для расчета (М)'!E34 -> 253.47 | J39: =I39*E39 -> #REF!
C40: Очистка стен от "жидких" обоев | D40: м2 | E40: =$A$6 -> #REF! | F40: ='Прайс для расчета'!E35 -> 205.758 | G40: =F40*E40 -> #REF! | I40: ='Прайс для расчета (М)'!E35 -> 102.879 | J40: =I40*E40 -> #REF!
C41: Очистка стен от шпаклевки* | D41: м2 | E41: =$A$6 -> #REF! | F41: ='Прайс для расчета'!E36 -> 205.758 | G41: =F41*E41 -> #REF! | I41: ='Прайс для расчета (М)'!E36 -> 102.879 | J41: =I41*E41 -> #REF!
C42: Ошкуривание поверхности(стены) | D42: м2 | E42: =$A$6 -> #REF! | F42: ='Прайс для расчета'!E37 -> 204.75 | G42: =F42*E42 -> #REF! | I42: ='Прайс для расчета (М)'!E37 -> 102.375 | J42: =I42*E42 -> #REF!
C43: Расшивка трещин/рустов | D43: м/п | E43: 1 | F43: ='Прайс для расчета'!E38 -> 292.236 | G43: =F43*E43 -> 292.236 | I43: ='Прайс для расчета (М)'!E38 -> 146.118 | J43: =I43*E43 -> 146.118
C44: Насечка стен | D44: м2 | E44: =$A$6 -> #REF! | F44: ='Прайс для расчета'!E39 -> 164.01 | G44: =F44*E44 -> #REF! | I44: ='Прайс для расчета (М)'!E39 -> 82.005 | J44: =I44*E44 -> #REF!
...

Sheet Кладовая(база)
A1: Периметр | T1: =G137 -> 0 | U1: =J137 -> 0
A2: =ROUND(D7*2+E7*2,2) -> 0 | T2: =G248 -> 0 | U2: =J248 -> 0
A3: Площадь пола | T3: =G362 -> 0 | U3: =J362 -> 0
A4: =ROUND(D7*E7,2) -> 0 | T4: 0 | U4: 0
A5: Площадь стен | C5: =#REF! -> #REF! | T5: 0 | U5: 0
A6: =ROUND(A2*F7-G7,2) -> #REF! | C6: Приложение№1 к договору №КС ____________ от ______________ 202_г. | D6: L,м/п | E6: B,м/п | F6: H,м/п | G6: Проем, м2 | I6: H,м/п | J6: Проем, м2 | T6: =G372 -> 0 | U6: =J372 -> 0
D7: 0 | E7: 0 | F7: =#REF! -> #REF! | G7: 0 | I7: =#REF! -> #REF! | J7: 0 | T7: =G373 -> 0 | U7: =J373 -> 0
C8: СМЕТА от "______"___________________202_г. | D8: =G375 -> #REF! | H8: Вып. | T8: =G375 -> #REF! | U8: =J375 -> 0
B10: =IF(SUM(B11:B136)>0,1,0) -> 0 | C10: Кладовая. Демонтажные работы | D10: ед. изм. | E10: кол-во | F10: цена | G10: сумма | I10: цена | J10: сумма
B11: =IF(SUM(B12:B32)>0,1,0) -> 0 | C11: Полы
C12: Демонтаж плинтуса | D12: м/п | E12: =$A$2 -> 0 | F12: ='Прайс для расчета'!E5 -> 89.25 | G12: =F12*E12 -> 0 | I12: ='Прайс для расчета (М)'!E5 -> 44.625 | J12: =I12*E12 -> 0
C13: Демонтаж ламината, паркетной доски | D13: м2 | E13: =$A$4 -> 0 | F13: ='Прайс для расчета'!E6 -> 157.5 | G13: =F13*E13 -> 0 | I13: ='Прайс для расчета (М)'!E6 -> 78.75 | J13: =I13*E13 -> 0
C14: Демонтаж паркета штучного | D14: м2 | E14: =$A$4 -> 0 | F14: ='Прайс для расчета'!E7 -> 292.236 | G14: =F14*E14 -> 0 | I14: ='Прайс для расчета (М)'!E7 -> 146.118 | J14: =I14*E14 -> 0
C15: Демонтаж паркета шитового | D15: м2 | E15: =$A$4 -> 0 | F15: ='Прайс для расчета'!E8 -> 367.5 | G15: =F15*E15 -> 0 | I15: ='Прайс для расчета (М)'!E8 -> 183.75 | J15: =I15*E15 -> 0
C16: Демонтаж линолеума, ковролина | D16: м2 | E16: =$A$4 -> 0 | F16: ='Прайс для расчета'!E9 -> 120.771 | G16: =F16*E16 -> 0 | I16: ='Прайс для расчета (М)'!E9 -> 60.3855 | J16: =I16*E16 -> 0
C17: Демонтаж фанеры, ДВП | D17: м2 | E17: =$A$4 -> 0 | F17: ='Прайс для расчета'!E10 -> 102.879 | G17: =F17*E17 -> 0 | I17: ='Прайс для расчета (М)'!E10 -> 51.4395 | J17: =I17*E17 -> 0
C18: Комплекс косметических демонтажных работ* | D18: м2 | E18: =$A$4 -> 0 | F18: ='Прайс для расчета'!E11 -> 1837.5 | G18: =F18*E18 -> 0 | I18: ='Прайс для расчета (М)'!E11 -> 918.75 | J18: =I18*E18 -> 0
C19: Комплекс капитальных демонтажных работ* | D19: м2 | E19: =$A$4 -> 0 | F19: ='Прайс для расчета'!E12 -> 2677.5 | G19: =F19*E19 -> 0 | I19: ='Прайс для расчета (М)'!E12 -> 1338.75 | J19: =I19*E19 -> 0
C20: Демонтаж покрытия из битумной мастики* | D20: м2 | E20: =$A$4 -> 0 | F20: ='Прайс для расчета'!E13 -> 367.5 | G20: =F20*E20 -> 0 | I20: ='Прайс для расчета (М)'!E13 -> 183.75 | J20: =I20*E20 -> 0
C21: Демонтаж деревянных полов | D21: м2 | E21: =$A$4 -> 0 | F21: ='Прайс для расчета'!E14 -> 315 | G21: =F21*E21 -> 0 | I21: ='Прайс для расчета (М)'!E14 -> 157.5 | J21: =I21*E21 -> 0
C22: Демонтаж лаг | D22: м2 | E22: =$A$4 -> 0 | F22: ='Прайс для расчета'!E15 -> 162.75 | G22: =F22*E22 -> 0 | I22: ='Прайс для расчета (М)'!E15 -> 81.375 | J22: =I22*E22 -> 0
C23: Удаление слоев из керамзита, песка | D23: м2 | E23: =$A$4 -> 0 | F23: ='Прайс для расчета'!E16 -> 162.75 | G23: =F23*E23 -> 0 | I23: ='Прайс для расчета (М)'!E16 -> 81.375 | J23: =I23*E23 -> 0
C24: Ремонт дощатых полов | D24: м2 | E24: =$A$4 -> 0 | F24: ='Прайс для расчета'!E17 -> 335.475 | G24: =F24*E24 -> 0 | I24: ='Прайс для расчета (М)'!E17 -> 167.7375 | J24: =I24*E24 -> 0
... C28: Демонтаж плитки | D28: м2 | E28: =$A$4 -> 0 | F28: ='Прайс для расчета'!E21 -> 262.5 | G28: =F28*E28 -> 0 | I28: ='Прайс для расчета (М)'!E21 -> 131.25 | J28: =I28*E28 -> 0
C29: Демонтаж бетонного бортика | D29: м/п | E29: =$A$2 -> 0 | F29: ='Прайс для расчета'!E22 -> 644.112 | G29: =F29*E29 -> 0 | I29: ='Прайс для расчета (М)'!E22 -> 322.056 | J29: =I29*E29 -> 0
C30: Демонтаж плинтуса из плитки | D30: м/п | E30: =$A$2 -> 0 | F30: ='Прайс для расчета'!E23 -> 111.825 | G30: =F30*E30 -> 0 | I30: ='Прайс для расчета (М)'!E23 -> 55.9125 | J30: =I30*E30 -> 0
C31: Демонтаж порога из плитки | D31: м/п | E31: 1 | F31: ='Прайс для расчета'!E24 -> 523.341 | G31: =F31*E31 -> 523.341 | I31: ='Прайс для расчета (М)'!E24 -> 261.6705 | J31: =I31*E31 -> 261.6705
C32: Расшивка плиточных швов(пол) | D32: м2 | E32: =$A$4 -> 0 | F32: ='Прайс для расчета'!E25 -> 335.475 | G32: =F32*E32 -> 0 | I32: ='Прайс для расчета (М)'!E25 -> 167.7375 | J32: =I32*E32 -> 0
B33: =IF(SUM(B34:B59)>0,1,0) -> 0 | C33: Стены
C34: Демонтаж пластикового уголка | D34: м/п | E34: 1 | F34: ='Прайс для расчета'!E29 -> 68.586 | G34: =F34*E34 -> 68.586 | I34: ='Прайс для расчета (М)'!E29 -> 34.293 | J34: =I34*E34 -> 34.293
C35: Сверление отверстия в ГКЛ | D35: шт | E35: 1 | F35: ='Прайс для расчета'!E30 -> 231 | G35: =F35*E35 -> 231 | I35: ='Прайс для расчета (М)'!E30 -> 115.5 | J35: =I35*E35 -> 115.5
C36: Снятие обоев(стены) | D36: м2 | E36: =$A$6 -> #REF! | F36: ='Прайс для расчета'!E31 -> 210 | G36: =F36*E36 -> #REF! | I36: ='Прайс для расчета (М)'!E31 -> 105 | J36: =I36*E36 -> #REF!
C37: Снятие побелки | D37: м2 | E37: =$A$6 -> #REF! | F37: ='Прайс для расчета'!E32 -> 205.758 | G37: =F37*E37 -> #REF! | I37: ='Прайс для расчета (М)'!E32 -> 102.879 | J37: =I37*E37 -> #REF!
C38: Очистка краски со стен* | D38: м2 | E38: =$A$6 -> #REF! | F38: ='Прайс для расчета'!E33 -> 205.758 | G38: =F38*E38 -> #REF! | I38: ='Прайс для расчета (М)'!E33 -> 102.879 | J38: =I38*E38 -> #REF!
C39: Очистка масляной краски со стен* | D39: м2 | E39: =$A$6 -> #REF! | F39: ='Прайс для расчета'!E34 -> 506.94 | G39: =F39*E39 -> #REF! | I39: ='Прайс для расчета (М)'!E34 -> 253.47 | J39: =I39*E39 -> #REF!
C40: Очистка стен от "жидких" обоев | D40: м2 | E40: =$A$6 -> #REF! | F40: ='Прайс для расчета'!E35 -> 205.758 | G40: =F40*E40 -> #REF! | I40: ='Прайс для расчета (М)'!E35 -> 102.879 | J40: =I40*E40 -> #REF!
C41: Очистка стен от шпаклевки* | D41: м2 | E41: =$A$6 -> #REF! | F41: ='Прайс для расчета'!E36 -> 205.758 | G41: =F41*E41 -> #REF! | I41: ='Прайс для расчета (М)'!E36 -> 102.879 | J41: =I41*E41 -> #REF!
C42: Ошкуривание поверхности(стены) | D42: м2 | E42: =$A$6 -> #REF! | F42: ='Прайс для расчета'!E37 -> 204.75 | G42: =F42*E42 -> #REF! | I42: ='Прайс для расчета (М)'!E37 -> 102.375 | J42: =I42*E42 -> #REF!
C43: Расшивка трещин/рустов | D43: м/п | E43: 1 | F43: ='Прайс для расчета'!E38 -> 292.236 | G43: =F43*E43 -> 292.236 | I43: ='Прайс для расчета (М)'!E38 -> 146.118 | J43: =I43*E43 -> 146.118
C44: Насечка стен | D44: м2 | E44: =$A$6 -> #REF! | F44: ='Прайс для расчета'!E39 -> 164.01 | G44: =F44*E44 -> #REF! | I44: ='Прайс для расчета (М)'!E39 -> 82.005 | J44: =I44*E44 -> #REF!
...

Sheet Смета по кладовой №1
A1: Периметр | T1: =G137 -> 0 | U1: =J137 -> 0
A2: 6.25 | T2: =G248 -> #REF! | U2: =J248 -> #REF!
A3: Площадь пола | T3: =G362 -> 14163.65 | U3: =J362 -> 6960.66
A4: 2.41 | D4: Гардероб 1 | T4: 0 | U4: 0
A5: Площадь стен | C5: =#REF! -> #REF! | T5: 0 | U5: 0
A6: =ROUND(A2*F7-G7,2) -> #REF! | C6: Приложение№1 к договору №КС ____________ от ______________ 202_г. | D6: L,м/п | E6: B,м/п | F6: H,м/п | G6: Проем, м2 | I6: H,м/п | J6: Проем, м2 | T6: =G372 -> 265.7025 | U6: =J372 -> 132.85125
D7: 0 | E7: 0 | F7: =#REF! -> #REF! | G7: 1.8 | I7: =#REF! -> #REF! | J7: 0 | T7: =G373 -> #REF! | U7: =J373 -> #REF!
C8: СМЕТА от "______"___________________202_г. | D8: =G375 -> #REF! | H8: Вып. | T8: =G375 -> #REF! | U8: =J375 -> #REF!
B10: =IF(SUM(B11:B136)>0,1,0) -> 0 | C10: Кладовая 1. Демонтажные работы | D10: ед. изм. | E10: кол-во | F10: цена | G10: сумма | I10: цена | J10: сумма
B11: =IF(SUM(B12:B32)>0,1,0) -> 0 | C11: Полы
C12: Демонтаж плинтуса | D12: м/п | E12: =$A$2 -> 6.25 | F12: ='Прайс для расчета'!E5 -> 89.25 | G12: =F12*E12 -> 557.8125 | I12: ='Прайс для расчета (М)'!E5 -> 44.625 | J12: =I12*E12 -> 278.90625
C13: Демонтаж ламината, паркетной доски | D13: м2 | E13: =$A$4 -> 2.41 | F13: ='Прайс для расчета'!E6 -> 157.5 | G13: =F13*E13 -> 379.575 | I13: ='Прайс для расчета (М)'!E6 -> 78.75 | J13: =I13*E13 -> 189.7875
C14: Демонтаж паркета штучного | D14: м2 | E14: =$A$4 -> 2.41 | F14: ='Прайс для расчета'!E7 -> 292.236 | G14: =F14*E14 -> 704.28876 | I14: ='Прайс для расчета (М)'!E7 -> 146.118 | J14: =I14*E14 -> 352.14438
C15: Демонтаж паркета шитового | D15: м2 | E15: =$A$4 -> 2.41 | F15: ='Прайс для расчета'!E8 -> 367.5 | G15: =F15*E15 -> 885.675 | I15: ='Прайс для расчета (М)'!E8 -> 183.75 | J15: =I15*E15 -> 442.8375
C16: Демонтаж линолеума, ковролина | D16: м2 | E16: =$A$4 -> 2.41 | F16: ='Прайс для расчета'!E9 -> 120.771 | G16: =F16*E16 -> 291.05811 | I16: ='Прайс для расчета (М)'!E9 -> 60.3855 | J16: =I16*E16 -> 145.52905
C17: Демонтаж фанеры, ДВП | D17: м2 | E17: =$A$4 -> 2.41 | F17: ='Прайс для расчета'!E10 -> 102.879 | G17: =F17*E17 -> 247.93839 | I17: ='Прайс для расчета (М)'!E10 -> 51.4395 | J17: =I17*E17 -> 123.96919
C18: Комплекс косметических демонтажных работ* | D18: м2 | E18: =$A$4 -> 2.41 | F18: ='Прайс для расчета'!E11 -> 1837.5 | G18: =F18*E18 -> 4428.375 | I18: ='Прайс для расчета (М)'!E11 -> 918.75 | J18: =I18*E18 -> 2214.1875
C19: Комплекс капитальных демонтажных работ* | D19: м2 | E19: =$A$4 -> 2.41 | F19: ='Прайс для расчета'!E12 -> 2677.5 | G19: =F19*E19 -> 6452.775 | I19: ='Прайс для расчета (М)'!E12 -> 1338.75 | J19: =I19*E19 -> 3226.3875
C20: Демонтаж покрытия из битумной мастики* | D20: м2 | E20: =$A$4 -> 2.41 | F20: ='Прайс для расчета'!E13 -> 367.5 | G20: =F20*E20 -> 885.675 | I20: ='Прайс для расчета (М)'!E13 -> 183.75 | J20: =I20*E20 -> 442.8375
C21: Демонтаж деревянных полов | D21: м2 | E21: =$A$4 -> 2.41 | F21: ='Прайс для расчета'!E14 -> 315 | G21: =F21*E21 -> 759.15 | I21: ='Прайс для расчета (М)'!E14 -> 157.5 | J21: =I21*E21 -> 379.575
C22: Демонтаж лаг | D22: м2 | E22: =$A$4 -> 2.41 | F22: ='Прайс для расчета'!E15 -> 162.75 | G22: =F22*E22 -> 392.2275 | I22: ='Прайс для расчета (М)'!E15 -> 81.375 | J22: =I22*E22 -> 196.11375
C23: Удаление слоев из керамзита, песка | D23: м2 | E23: =$A$4 -> 2.41 | F23: ='Прайс для расчета'!E16 -> 162.75 | G23: =F23*E23 -> 392.2275 | I23: ='Прайс для расчета (М)'!E16 -> 81.375 | J23: =I23*E23 -> 196.11375
C24: Ремонт дощатых полов | D24: м2 | E24: =$A$4 -> 2.41 | F24: ='Прайс для расчета'!E17 -> 335.475 | G24: =F24*E24 -> 808.49475 | I24: ='Прайс для расчета (М)'!E17 -> 167.7375 | J24: =I24*E24 -> 404.24738
... C28: Демонтаж плитки | D28: м2 | E28: =$A$4 -> 2.41 | F28: ='Прайс для расчета'!E21 -> 262.5 | G28: =F28*E28 -> 632.625 | I28: ='Прайс для расчета (М)'!E21 -> 131.25 | J28: =I28*E28 -> 316.3125
C29: Демонтаж бетонного бортика | D29: м/п | E29: =$A$2 -> 6.25 | F29: ='Прайс для расчета'!E22 -> 644.112 | G29: =F29*E29 -> 4025.7 | I29: ='Прайс для расчета (М)'!E22 -> 322.056 | J29: =I29*E29 -> 2012.85
C30: Демонтаж плинтуса из плитки | D30: м/п | E30: =$A$2 -> 6.25 | F30: ='Прайс для расчета'!E23 -> 111.825 | G30: =F30*E30 -> 698.90625 | I30: ='Прайс для расчета (М)'!E23 -> 55.9125 | J30: =I30*E30 -> 349.45312
C31: Демонтаж порога из плитки | D31: м/п | E31: 1 | F31: ='Прайс для расчета'!E24 -> 523.341 | G31: =F31*E31 -> 523.341 | I31: ='Прайс для расчета (М)'!E24 -> 261.6705 | J31: =I31*E31 -> 261.6705
C32: Расшивка плиточных швов(пол) | D32: м2 | E32: =$A$4 -> 2.41 | F32: ='Прайс для расчета'!E25 -> 335.475 | G32: =F32*E32 -> 808.49475 | I32: ='Прайс для расчета (М)'!E25 -> 167.7375 | J32: =I32*E32 -> 404.24738
B33: =IF(SUM(B34:B59)>0,1,0) -> 0 | C33: Стены
C34: Демонтаж пластикового уголка | D34: м/п | E34: 1 | F34: ='Прайс для расчета'!E29 -> 68.586 | G34: =F34*E34 -> 68.586 | I34: ='Прайс для расчета (М)'!E29 -> 34.293 | J34: =I34*E34 -> 34.293
C35: Сверление отверстия в ГКЛ | D35: шт | E35: 1 | F35: ='Прайс для расчета'!E30 -> 231 | G35: =F35*E35 -> 231 | I35: ='Прайс для расчета (М)'!E30 -> 115.5 | J35: =I35*E35 -> 115.5
C36: Снятие обоев(стены) | D36: м2 | E36: =$A$6 -> #REF! | F36: ='Прайс для расчета'!E31 -> 210 | G36: =F36*E36 -> #REF! | I36: ='Прайс для расчета (М)'!E31 -> 105 | J36: =I36*E36 -> #REF!
C37: Снятие побелки | D37: м2 | E37: =$A$6 -> #REF! | F37: ='Прайс для расчета'!E32 -> 205.758 | G37: =F37*E37 -> #REF! | I37: ='Прайс для расчета (М)'!E32 -> 102.879 | J37: =I37*E37 -> #REF!
C38: Очистка краски со стен* | D38: м2 | E38: =$A$6 -> #REF! | F38: ='Прайс для расчета'!E33 -> 205.758 | G38: =F38*E38 -> #REF! | I38: ='Прайс для расчета (М)'!E33 -> 102.879 | J38: =I38*E38 -> #REF!
C39: Очистка масляной краски со стен* | D39: м2 | E39: =$A$6 -> #REF! | F39: ='Прайс для расчета'!E34 -> 506.94 | G39: =F39*E39 -> #REF! | I39: ='Прайс для расчета (М)'!E34 -> 253.47 | J39: =I39*E39 -> #REF!
C40: Очистка стен от "жидких" обоев | D40: м2 | E40: =$A$6 -> #REF! | F40: ='Прайс для расчета'!E35 -> 205.758 | G40: =F40*E40 -> #REF! | I40: ='Прайс для расчета (М)'!E35 -> 102.879 | J40: =I40*E40 -> #REF!
C41: Очистка стен от шпаклевки* | D41: м2 | E41: =$A$6 -> #REF! | F41: ='Прайс для расчета'!E36 -> 205.758 | G41: =F41*E41 -> #REF! | I41: ='Прайс для расчета (М)'!E36 -> 102.879 | J41: =I41*E41 -> #REF!
C42: Ошкуривание поверхности(стены) | D42: м2 | E42: =$A$6 -> #REF! | F42: ='Прайс для расчета'!E37 -> 204.75 | G42: =F42*E42 -> #REF! | I42: ='Прайс для расчета (М)'!E37 -> 102.375 | J42: =I42*E42 -> #REF!
C43: Расшивка трещин/рустов | D43: м/п | E43: 1 | F43: ='Прайс для расчета'!E38 -> 292.236 | G43: =F43*E43 -> 292.236 | I43: ='Прайс для расчета (М)'!E38 -> 146.118 | J43: =I43*E43 -> 146.118
C44: Насечка стен | D44: м2 | E44: =$A$6 -> #REF! | F44: ='Прайс для расчета'!E39 -> 164.01 | G44: =F44*E44 -> #REF! | I44: ='Прайс для расчета (М)'!E39 -> 82.005 | J44: =I44*E44 -> #REF!
...

Sheet Смета по кладовой №2
A1: Периметр | T1: =G137 -> 0 | U1: =J137 -> 0
A2: 6.94 | T2: =G248 -> #REF! | U2: =J248 -> #REF!
A3: Площадь пола | T3: =G362 -> 9490.9778 | U3: =J362 -> 4624.3239
A4: 2.46 | D4: Гардероб 2 | T4: 0 | U4: 0
A5: Площадь стен | C5: =#REF! -> #REF! | T5: 0 | U5: 0
A6: =ROUND(A2*F7-G7,2) -> #REF! | C6: Приложение№1 к договору №КС ____________ от ______________ 202_г. | D6: L,м/п | E6: B,м/п | F6: H,м/п | G6: Проем, м2 | I6: H,м/п | J6: Проем, м2 | T6: =G372 -> 271.215 | U6: =J372 -> 135.6075
D7: 0 | E7: 0 | F7: =#REF! -> #REF! | G7: 1.8 | I7: =#REF! -> #REF! | J7: 0 | T7: =G373 -> #REF! | U7: =J373 -> #REF!
C8: СМЕТА от "______"___________________202_г. | D8: =G375 -> #REF! | H8: Вып. | T8: =G375 -> #REF! | U8: =J375 -> #REF!
B10: =IF(SUM(B11:B136)>0,1,0) -> 0 | C10: Кладовая 2. Демонтажные работы | D10: ед. изм. | E10: кол-во | F10: цена | G10: сумма | I10: цена | J10: сумма
B11: =IF(SUM(B12:B32)>0,1,0) -> 0 | C11: Полы
C12: Демонтаж плинтуса | D12: м/п | E12: =$A$2 -> 6.94 | F12: ='Прайс для расчета'!E5 -> 89.25 | G12: =F12*E12 -> 619.395 | I12: ='Прайс для расчета (М)'!E5 -> 44.625 | J12: =I12*E12 -> 309.6975
C13: Демонтаж ламината, паркетной доски | D13: м2 | E13: =$A$4 -> 2.46 | F13: ='Прайс для расчета'!E6 -> 157.5 | G13: =F13*E13 -> 387.45 | I13: ='Прайс для расчета (М)'!E6 -> 78.75 | J13: =I13*E13 -> 193.725
C14: Демонтаж паркета штучного | D14: м2 | E14: =$A$4 -> 2.46 | F14: ='Прайс для расчета'!E7 -> 292.236 | G14: =F14*E14 -> 718.90056 | I14: ='Прайс для расчета (М)'!E7 -> 146.118 | J14: =I14*E14 -> 359.45028
C15: Демонтаж паркета шитового | D15: м2 | E15: =$A$4 -> 2.46 | F15: ='Прайс для расчета'!E8 -> 367.5 | G15: =F15*E15 -> 904.05 | I15: ='Прайс для расчета (М)'!E8 -> 183.75 | J15: =I15*E15 -> 452.025
C16: Демонтаж линолеума, ковролина | D16: м2 | E16: =$A$4 -> 2.46 | F16: ='Прайс для расчета'!E9 -> 120.771 | G16: =F16*E16 -> 297.09666 | I16: ='Прайс для расчета (М)'!E9 -> 60.3855 | J16: =I16*E16 -> 148.54833
C17: Демонтаж фанеры, ДВП | D17: м2 | E17: =$A$4 -> 2.46 | F17: ='Прайс для расчета'!E10 -> 102.879 | G17: =F17*E17 -> 253.08234 | I17: ='Прайс для расчета (М)'!E10 -> 51.4395 | J17: =I17*E17 -> 126.54117
C18: Комплекс косметических демонтажных работ* | D18: м2 | E18: =$A$4 -> 2.46 | F18: ='Прайс для расчета'!E11 -> 1837.5 | G18: =F18*E18 -> 4520.25 | I18: ='Прайс для расчета (М)'!E11 -> 918.75 | J18: =I18*E18 -> 2260.125
C19: Комплекс капитальных демонтажных работ* | D19: м2 | E19: =$A$4 -> 2.46 | F19: ='Прайс для расчета'!E12 -> 2677.5 | G19: =F19*E19 -> 6586.65 | I19: ='Прайс для расчета (М)'!E12 -> 1338.75 | J19: =I19*E19 -> 3293.325
C20: Демонтаж покрытия из битумной мастики* | D20: м2 | E20: =$A$4 -> 2.46 | F20: ='Прайс для расчета'!E13 -> 367.5 | G20: =F20*E20 -> 904.05 | I20: ='Прайс для расчета (М)'!E13 -> 183.75 | J20: =I20*E20 -> 452.025
C21: Демонтаж деревянных полов | D21: м2 | E21: =$A$4 -> 2.46 | F21: ='Прайс для расчета'!E14 -> 315 | G21: =F21*E21 -> 774.9 | I21: ='Прайс для расчета (М)'!E14 -> 157.5 | J21: =I21*E21 -> 387.45
C22: Демонтаж лаг | D22: м2 | E22: =$A$4 -> 2.46 | F22: ='Прайс для расчета'!E15 -> 162.75 | G22: =F22*E22 -> 400.365 | I22: ='Прайс для расчета (М)'!E15 -> 81.375 | J22: =I22*E22 -> 200.1825
C23: Удаление слоев из керамзита, песка | D23: м2 | E23: =$A$4 -> 2.46 | F23: ='Прайс для расчета'!E16 -> 162.75 | G23: =F23*E23 -> 400.365 | I23: ='Прайс для расчета (М)'!E16 -> 81.375 | J23: =I23*E23 -> 200.1825
C24: Ремонт дощатых полов | D24: м2 | E24: =$A$4 -> 2.46 | F24: ='Прайс для расчета'!E17 -> 335.475 | G24: =F24*E24 -> 825.2685 | I24: ='Прайс для расчета (М)'!E17 -> 167.7375 | J24: =I24*E24 -> 412.63425
... C28: Демонтаж плитки | D28: м2 | E28: =$A$4 -> 2.46 | F28: ='Прайс для расчета'!E21 -> 262.5 | G28: =F28*E28 -> 645.75 | I28: ='Прайс для расчета (М)'!E21 -> 131.25 | J28: =I28*E28 -> 322.875
C29: Демонтаж бетонного бортика | D29: м/п | E29: =$A$2 -> 6.94 | F29: ='Прайс для расчета'!E22 -> 644.112 | G29: =F29*E29 -> 4470.1373 | I29: ='Прайс для расчета (М)'!E22 -> 322.056 | J29: =I29*E29 -> 2235.0686
C30: Демонтаж плинтуса из плитки | D30: м/п | E30: =$A$2 -> 6.94 | F30: ='Прайс для расчета'!E23 -> 111.825 | G30: =F30*E30 -> 776.0655 | I30: ='Прайс для расчета (М)'!E23 -> 55.9125 | J30: =I30*E30 -> 388.03275
C31: Демонтаж порога из плитки | D31: м/п | E31: 1 | F31: ='Прайс для расчета'!E24 -> 523.341 | G31: =F31*E31 -> 523.341 | I31: ='Прайс для расчета (М)'!E24 -> 261.6705 | J31: =I31*E31 -> 261.6705
C32: Расшивка плиточных швов(пол) | D32: м2 | E32: =$A$4 -> 2.46 | F32: ='Прайс для расчета'!E25 -> 335.475 | G32: =F32*E32 -> 825.2685 | I32: ='Прайс для расчета (М)'!E25 -> 167.7375 | J32: =I32*E32 -> 412.63425
B33: =IF(SUM(B34:B59)>0,1,0) -> 0 | C33: Стены
C34: Демонтаж пластикового уголка | D34: м/п | E34: 1 | F34: ='Прайс для расчета'!E29 -> 68.586 | G34: =F34*E34 -> 68.586 | I34: ='Прайс для расчета (М)'!E29 -> 34.293 | J34: =I34*E34 -> 34.293
