Workbook

Sheet Table 1
A1: Студия ремонта квартир в Москве и МО | E1: Портфолио WhatsApp 8 (495) 532-40-24
A2: *Адрес объекта: "Затонная 4 "
A3: Сводная смета
A4: площади | B4: Коридор №1 | C4: Коридор №2 | D4: Кухня №1 | F4: Комната №1 | G4: Комната №2 | H4: Электрика | I4: Сантехника | J4: Итого
A5: площадь пола | B5: 7.87 | C5: 2.2 | D5: 8.29 | F5: 16.9 | G5: 13.12 | H5: остаток | I5: радиаторы | J5: 48.38
A6: площадь стен | B6: 25.2 | C6: 7.5 | D6: 27.68 | F6: 35.51 | G6: 32.27 | J6: 128.16
A7: наименование работ | B7: Коридор №1 | C7: Коридор №2 | D7: Кухня №1 | F7: Комната №1 | G7: Комната №2 | J7: Итого
A8: ИТОГО ПО РАБОТАМ | B8: ='Table 2'!F11 -> 24212.25 | C8: ='Table 3'!F12 -> 10285.68 | D8: ='Table 4'!E26 -> 101973.85 | F8: ='Table 5'!E19 -> 50764.27 | G8: ='Table 6'!E19 -> 47513.59 | H8: 58229 | I8: 5700 | J8: =B8+C8+D8+F8+G8+H8+I8 -> 298678.64

Sheet Table 2
A1: *Адрес объекта: "Затонная 4 "
A2: Приложение№1 к договору №КС от 202_г.
A4: СМЕТА от " " 202_г.
A5: Коридор 1. Чистовые отделочные работы | C5: ед. изм. | D5: кол-во | E5: цена | F5: сумма
A6: Покраска потолка | C6: м2 | D6: 6.35 | E6: 550 | F6: =D6*E6 -> 3492.5
A7: Укладка кварцвинила | C7: м2 | D7: 6.35 | E7: 835 | F7: =D7*E7 -> 5302.25
A8: Монтаж плинтусов пластиковых | C8: м/п | D8: 10 | E8: 214 | F8: =D8*E8 -> 2140
A9: Оклейка стен обоями без подбора* | C9: м2 | D9: 23.5 | E9: 565 | F9: =D9*E9 -> 13277.5
A10: Итого по разделу(чистовые отделочные работы) | F10: =F7+F8+F9+F6 -> 24212.25
A11: ИТОГО ПО ПОМЕЩЕНИЮ. СТОИМОСТЬ РАБОТ | F11: =F10 -> 24212.25
A12: Составлено: Согласовано:
A14: (подпись)
E15: =13.67*2.63 -> 35.9521
A16: (подпись)

Sheet Table 3
A1: *Адрес объекта: "Затонная 4 "
A2: Приложение№1 к договору №КС от 202_г. | C2: L,м/п | D2: B,м/п | E2: H,м/п | F2: Проем, м2
C3: 2.11 | D3: 1.04 | E3: 2.5 | F3: 8.28
A4: СМЕТА от " " 202_г. | C4: 24367.68
A6: Коридор 2. Чистовые отделочные работы | C6: ед. изм. | D6: кол-во | E6: цена | F6: сумма
A7: Покраска потолка | C7: м2 | D7: 2.78 | E7: 550 | F7: =D7*E7 -> 1529
A8: Укладка кварцвинила | C8: м2 | D8: 2.78 | E8: 835 | F8: =E8*D8 -> 2321.3
A9: Монтаж плинтусов пластиковых | C9: м/п | D9: 3.67 | E9: 214 | F9: =E9*D9 -> 785.38
A10: Оклейка стен обоями без подбора* | C10: м2 | D10: 10 | E10: 565 | F10: =E10*D10 -> 5650
A11: Итого по разделу(чистовые отделочные работы) | F11: =F8+F9+F10+F7 -> 10285.68
A12: ИТОГО ПО ПОМЕЩЕНИЮ. СТОИМОСТЬ РАБОТ | F12: =F11 -> 10285.68
A13: Составлено: Согласовано:
A15: (подпись)
A17: (подпись)

Sheet Table 4
A1: Кухня
A2: *Адрес объекта: "Затонная 4 "
A3: Приложение№1 к договору №КС от 202_г. | B3: L,м/п | C3: B,м/п | D3: H,м/п | E3: Проем, м2
B4: 2.86 | C4: 2.73 | D4: 2.5 | E4: 4.48
A5: СМЕТА от " " 202_г. | B5: 123833.19
A7: Кухня 1. Чистовые отделочные работы | B7: ед. изм. | C7: кол-во | D7: цена | E7: сумма
A8: Полы
A9: Укладка кварцвинила | B9: м2 | C9: 4.5 | D9: 835 | E9: =D9*C9 -> 3757.5
A10: Монтаж плинтусов пластиковых | B10: м/п | C10: 10.4 | D10: 214 | E10: =D10*C10 -> 2225.6
A11: Стены
A12: Облицовка плиткой стен (менее 300x300) | B12: мп | C12: =1.5*2.7 -> 4.05 | D12: 3350 | E12: =D12*C12 -> 13567.5
A13: Затирка плитки цементная (стены) | B13: мп | C13: =C12 -> 4.05 | D13: 395 | E13: =D13*C13 -> 1599.75
A14: Подрезка керамической плитки | B14: м/п | C14: 2.7 | D14: 485 | E14: =D14*C14 -> 1309.5
A15: Облицовка плиткой 400*80мм | B15: мп | C15: =2.6*4 -> 10.4 | D15: 3250 | E15: =D15*C15 -> 33800
A16: Затирка плитки цементная (полуколона) | B16: мп | C16: =C15 -> 10.4 | D16: 385 | E16: =D16*C16 -> 4004
A17: Запил плитки на 45 гр | B17: мп | C17: 15.6 | D17: 1284 | E17: =D17*C17 -> 20030.4
A18: Оклейка стен обоями без подбора* | B18: м2 | C18: 2 | D18: 565 | E18: =D18*C18 -> 1130
A19: Оклейка стен фотообоями | B19: м2 | C19: 12 | D19: 1125 | E19: =D19*C19 -> 13500
A20: Откосы
A21: Окраска откосов, углов | B21: м/п | C21: 4.63 | D21: 300 | E21: =D21*C21 -> 1389
A22: Потолок
A23: Окраска потолков | B23: м2 | C23: 8.29 | D23: 550 | E23: =D23*C23 -> 4559.5
A24: Установка карнизов | B24: м/п | C24: 2.86 | D24: 385 | E24: =D24*C24 -> 1101.1
A25: Итого по разделу(чистовые отделочные работы) | E25: =SUM(E9:E24) -> 101973.85
A26: ИТОГО ПО ПОМЕЩЕНИЮ. СТОИМОСТЬ РАБОТ со скидкой 15% | E26: =E25 -> 101973.85
A27: Составлено: Согласовано:
A28: (подпись) (подпись)

Sheet Table 5
A1: Гостиная
A2: *Адрес объекта: "Затонная 4 "
A3: Приложение№1 к договору № КС от 202_г. | B3: L,м/п | C3: B,м/п | D3: H,м/п | E3: Проем, м2
B4: 4.04 | C4: 4.19 | D4: 2.5 | E4: 5.62
A5: СМЕТА от " " 202_г. | B5: 153984.55
A7: Комната 1. Чистовые отделочные работы | B7: ед. изм. | C7: кол-во | D7: цена | E7: сумма
A8: Полы
A9: Укладка кварцвинила | B9: м2 | C9: 16.9 | D9: 835 | E9: =D9*C9 -> 14111.5
A10: Монтаж плинтусов пластиковых | B10: м/п | C10: 8.23 | D10: 214 | E10: =D10*C10 -> 1761.22
A11: Стены
A12: Оклейка стен обоями без подбора* | B12: м2 | C12: 35.51 | D12: 565 | E12: =D12*C12 -> 20063.15
A13: Откосы
A14: Окраска откосов, углов | B14: м/п | C14: 13.26 | D14: 300 | E14: =D14*C14 -> 3978
A15: Потолок
A16: Окраска потолков | B16: м2 | C16: 16.9 | D16: 550 | E16: =D16*C16 -> 9295
A17: Установка карнизов | B17: м/п | C17: 4.04 | D17: 385 | E17: =D17*C17 -> 1555.4
A18: Итого по разделу(чистовые отделочные работы) | E18: =SUM(E9:E17) -> 50764.27
A19: ИТОГО ПО ПОМЕЩЕНИЮ. СТОИМОСТЬ РАБОТ со скидкой 15% | E19: =E18 -> 50764.27
A20: Составлено: Согласовано:
A21: (подпись) (подпись)

Sheet Table 6
A1: Спальня
A2: *Адрес объекта: "Затонная 4 "
A3: Приложение№1 к договору № КС от 202_г. | B3: L,м/п | C3: B,м/п | D3: H,м/п | E3: Проем, м2
B4: 2.84 | C4: 4.62 | D4: 2.5 | E4: 5.03
A5: СМЕТА от " " 202_г. | B5: 131813.39
A6: Комната 2. Чистовые отделочные работы | B6: ед. изм. | C6: кол-во | D6: цена | E6: сумма
A7: Полы
A8: Укладка кварцвинила | B8: м2 | C8: 13.12 | D8: 835 | E8: =D8*C8 -> 10955.2
A9: Монтаж плинтусов пластиковых | B9: м/п | C9: 7.46 | D9: 214 | E9: =D9*C9 -> 1596.44
A10: Стены
A11: Оклейка стен обоями без подбора* | B11: м2 | C11: =32.27-8.5 -> 23.77 | D11: 565 | E11: =D11*C11 -> 13430.05
A12: Оклейка стен фотообоями | B12: м2 | C12: 8.5 | D12: 1125 | E12: =D12*C12 -> 9562.5
A13: Откосы
A14: Окраска откосов, углов | B14: м/п | C14: 12.2 | D14: 300 | E14: =D14*C14 -> 3660
A15: Потолок
A16: Окраска потолков | B16: м2 | C16: 13.12 | D16: 550 | E16: =D16*C16 -> 7216
A17: Установка карнизов | B17: м/п | C17: 2.84 | D17: 385 | E17: =D17*C17 -> 1093.4
A18: Итого по разделу(чистовые отделочные работы) | E18: =SUM(E8:E17) -> 47513.59
A19: ИТОГО ПО ПОМЕЩЕНИЮ. СТОИМОСТЬ РАБОТ | E19: =E18 -> 47513.59
A20: Составлено: Согласовано:
A21: (подпись) (подпись)

Sheet Электрика
A1: *Адрес объекта: "Затонная 4 "
A2: Приложение№1 к договору №КС от 202_г. | C2: L,м/п | D2: B,м/п | E2: H,м/п | F2: Проем, м2
C3: 0 | D3: 0 | E3: 2.5 | F3: 0
A4: СМЕТА от " " 202_г. | C4: 135489.62
A6: Электромонтажные работы | C6: ед. изм | D6: Кол-во | E6: цена | F6: сумма
A7: Штробление кирпичных, блочных стен под элкабель | C7: м/пм/п | D7: 37 | E7: 425 | F7: 15725
A8: Штробление бетонных стен под элкабель | C8: м/пм/п | D8: 20 | E8: 585 | F8: 11700
A9: Заделка и грунтовка штробЗаделка и грунтовка штроб | C9: м/пм/п | D9: 37 | E9: 95 | F9: 3515
A10: Установка механизма, панели электроточки | C10: штшт | D10: 30 | E10: 575 | F10: 17250
A11: Установка электроточки в кирпиче, блоке | C11: штшт | D11: 18 | E11: 695 | F11: 12510
A12: Установка электроточки в бетонеУстановка электроточки в бетоне | C12: штшт | D12: 12 | E12: 855 | F12: 10260
A13: Прокладка кабеляПрокладка кабеля | C13: м/пм/п | D13: 75 | E13: 92.3 | F13: 6922.5
A14: Прокладка кабеля в ПВХ трубе (по полу) | C14: м/пм/п | D14: 185 | E14: 213 | F14: 39405
A15: Установка автоматического выключателя | C15: штшт | D15: 10 | E15: 850 | F15: 8500
A16: Установка дифф автоматического выключателя | C16: штшт | D16: 3 | E16: 950 | F16: 2850
A17: Установка УЗОУстановка УЗО | C17: штшт | D17: 1 | E17: 1050 | F17: 1050
A18: Подключение к вводному щиту | C18: штшт | D18: 1 | E18: 1469.7 | F18: 1469.7
... A20: Монтаж элщита слаботочного | C20: штшт | D20: 1 | E20: 2127.16 | F20: 2127.16
A21: Итого | F21: =SUM(F7:F20) -> 135489.62
A23: Штробление кирпичных, блочных стен под элкабель | C23: м/п | D23: 4 | E23: 425 | F23: =E23*D23 -> 1700
A24: Штробление бетонных стен под элкабель | C24: м/п | D24: 36 | E24: 585 | F24: =E24*D24 -> 21060
A25: Штробление бетонных потолков под элкабель | C25: м/п | D25: 8 | E25: 885 | F25: =E25*D25 -> 7080
A26: Заделка и грунтовка штроб | C26: м/п | D26: 40 | E26: 95 | F26: =E26*D26 -> 3800
A27: Установка механизма, панели электроточки | C27: шт | D27: 54 | E27: 575 | F27: =E27*D27 -> 31050
A28: Установка электроточки в кирпиче, блоке | C28: шт | D28: 3 | E28: 695 | F28: =E28*D28 -> 2085
A29: Установка электроточки в бетоне | C29: шт | D29: 51 | E29: 855 | F29: =E29*D29 -> 43605
A30: Прокладка кабеля | C30: м/п | D30: 80 | E30: 92.3 | F30: =E30*D30 -> 7384
A31: Прокладка кабеля в ПВХ трубе (по полу) | C31: м/п | D31: 160 | E31: 213 | F31: =E31*D31 -> 34080
A32: Установка автоматического выключателя | C32: шт | D32: 12 | E32: 850 | F32: =E32*D32 -> 10200
A33: Установка дифф автоматического выключателя | C33: шт | D33: 3 | E33: 950 | F33: =E33*D33 -> 2850
A34: Подключение к вводному щиту | C34: шт | D34: 1 | E34: 1469.7 | F34: =E34*D34 -> 1469.7
... A38: Монтаж люстры (без сборки) | C38: шт | D38: 3 | E38: 1350 | F38: =E38*D38 -> 4050
A39: Итого по разделу(электромонтажные работы)Итого по разделу(электромонтажные работы) | F39: =SUM(F23:F38) -> 187613.7
A40: Остаток около | F40: =F39-129384 -> 58229.7
A42: (подпись)

Sheet Table 9
A2: Приложение №2
A3: Прайс Лист
A4: цены актуальны до 30.06.2025 г.
A5: Наименование работ | B5: Цена
A6: Демонтажные работы
A7: Демонтаж плинтуса | B7: 85 | C7: м/п
A8: Расключение элищта слаботочного | B8: 150 | C8: м2
A9: Демонтаж паркета штучного | B9: 278 | C9: м2
A10: Демонтаж паркета шитового | B10: 350 | C10: м2
A11: Демонтаж линолеума, ковролина | B11: 115 | C11: м2
A12: Демонтаж фанеры, ДВП | B12: 98 | C12: м2
A13: Комплекс косметических демонтажных работ: Пол: снятие чистового напольного покрытия и напольного плинтуса без демонтажа стяжки, Стены: демонтаж чистового покрытия обои или краска и очисткой стен от старой шпатлевки Потолок очистка от старой краски или демонтаж конструкции из ГКЛ с очисткой поверхности от шпатлевки РАБОТЫ Демонтажные работы по потолкам производятся по необходимости и на усмотрение прораба! | B13: 1750 | C13: м2
A14: Комплекс капитальный демонтажных работ: Пол: снятие старого напольного покрытия и отбивка стяжки, Стены:Снятие всех покрытий с учетом отбивки старой штукатурки или нанесения засечек под штукатурные работы, Потолок: демонтаж всех старых покрытий и конструкции. Демонтажные работы по потолкам производятся по необходимости и на усмотрение прораба! | B14: 2550 | C14: м2
A15: Демонтаж покрытия из битумной мастики* | B15: 350 | C15: м2
A16: Демонтаж деревянных полов | B16: 300 | C16: м2
A17: Демонтаж лаг | B17: 155 | C17: м2
A18: Удаление слоев из керамзита, песка | B18: 155 | C18: м2
... A126: Штробление ниши под элщит(кирпич/пеноблок) | B126: 4043 | C126: шт
A127: Полы. Черновые работы
A128: Грунтовка пола 1 слой | B128: 90 | C128: м2
A129: Грунтовка пола(бетоноконтактом) 1 слой | B129: 109 | C129: м2
A130: Устройство наливных полов (до 1 см) | B130: 549 | C130: м2
A131: Устройство наливных полов (до 3 см) | B131: 649 | C131: м2
A132: Устройство стяжки по маякам до 4 см | B132: 849 | C132: м2
A133: Устройство стяжки по маякам до 6 см | B133: 949 | C133: м2
A134: Устройство стяжки по маякам свыше 6 см до 10 см | B134: 1049 | C134: м2
A135: Железнение стяжки | B135: 259 | C135: м2
A136: Укладка сетки(для стяжки) | B136: 250 | C136: м2
A137: Монтаж демферной ленты(кромочной ленты) | B137: 239 | C137: м2
A138: Обработка антиплесенью | B138: 195 | C138: м2/мп
A139: Подсыпка керамзита | B139: 285 | C139: м2
... A150: Укладка ДВП | B150: 450 | C150: м2
A151: Стены. Черновые Работы
A152: Грунтовка стен(бетоноконтактом) 1 слой | B152: 119 | C152: м2
A153: Штукатурка стен по маякам высококачественная до 2 см | B153: 850 | C153: м2
A154: Штукатурка стен по маякам высококачественная до 5 см | B154: 1150 | C154: м2
A155: Штукатурка стен по маякам улучшенная до 2 см гипсовая | B155: 595 | C155: м2
A156: Штукатурка стен по маякам улучшенная до 2 см цементной смесью | B156: 695 | C156: м2
A157: Штукатурка стен по маякам улучшенная до 5 см | B157: 899 | C157: м2
A158: Штукатурка стен простая (под правило) | B158: 750 | C158: м2
...
